/**
 * Zollern Galaxy by @author Zollern Wolf
 * Copyright 2016 - 2025
 * You may use this code to learn from,
 * but do not claim it as your own, and
 * do not redistribute it.
 */
package io.github.nagol2003.testing.experimental;

import java.util.Random;

import net.minecraft.block.BlockStairs;
import net.minecraft.block.state.IBlockState;
import net.minecraft.init.Blocks;
import net.minecraft.util.EnumFacing;
import net.minecraft.util.math.BlockPos;
import net.minecraft.world.World;

public class WorldGenBattleTower extends ZGWorldGenMaster {
	
	private IBlockState cobbleState = Blocks.COBBLESTONE.getDefaultState();
	private IBlockState bedrockState = Blocks.BEDROCK.getDefaultState();
	private IBlockState glassState = Blocks.GLASS.getDefaultState();
	private IBlockState airState = Blocks.AIR.getDefaultState();
	private IBlockState stairState = Blocks.STONE_STAIRS.getDefaultState().withProperty(BlockStairs.FACING, EnumFacing.NORTH);
	private IBlockState slabState = Blocks.STONE_SLAB.getDefaultState();
	private IBlockState ironBarState = Blocks.IRON_BARS.getDefaultState();
	
	public WorldGenBattleTower(IBlockState cobbleStateIn, IBlockState bedrockStateIn) {
		this.cobbleState = cobbleStateIn;
		this.bedrockState = bedrockStateIn;
	}
	
	@Override
	public boolean generate(World world, Random rand, BlockPos position) {
		if (!this.isValidSpawn(world, position)) {
			return false;
		}
		
		this.setBlock(world, position.add(0, 0, 0), this.cobbleState);
		this.setBlock(world, position.add(0, 0, 1), this.cobbleState);
		this.setBlock(world, position.add(0, 0, 2), this.cobbleState);
		this.setBlock(world, position.add(0, 0, 3), this.cobbleState);
		this.setBlock(world, position.add(0, 0, 4), this.cobbleState);
		this.setBlock(world, position.add(0, 0, 5), this.cobbleState);
		this.setBlock(world, position.add(0, 0, 6), this.cobbleState);
		this.setBlock(world, position.add(0, 0, 7), this.cobbleState);
		this.setBlock(world, position.add(0, 0, 8), this.cobbleState);
		this.setBlock(world, position.add(0, 0, 9), this.cobbleState);
		this.setBlock(world, position.add(0, 0, 10), this.cobbleState);
		this.setBlock(world, position.add(0, 1, 0), this.cobbleState);
		this.setBlock(world, position.add(0, 1, 1), this.cobbleState);
		this.setBlock(world, position.add(0, 1, 2), this.cobbleState);
		this.setBlock(world, position.add(0, 1, 3), this.cobbleState);
		this.setBlock(world, position.add(0, 1, 4), this.cobbleState);
		this.setBlock(world, position.add(0, 1, 5), this.cobbleState);
		this.setBlock(world, position.add(0, 1, 6), this.cobbleState);
		this.setBlock(world, position.add(0, 1, 7), this.cobbleState);
		this.setBlock(world, position.add(0, 1, 8), this.cobbleState);
		this.setBlock(world, position.add(0, 1, 9), this.cobbleState);
		this.setBlock(world, position.add(0, 1, 10), this.cobbleState);
		this.setBlock(world, position.add(0, 2, 0), this.cobbleState);
		this.setBlock(world, position.add(0, 2, 1), this.cobbleState);
		this.setBlock(world, position.add(0, 2, 2), this.cobbleState);
		this.setBlock(world, position.add(0, 2, 3), this.cobbleState);
		this.setBlock(world, position.add(0, 2, 4), this.cobbleState);
		this.setBlock(world, position.add(0, 2, 5), this.cobbleState);
		this.setBlock(world, position.add(0, 2, 6), this.cobbleState);
		this.setBlock(world, position.add(0, 2, 7), this.cobbleState);
		this.setBlock(world, position.add(0, 2, 8), this.cobbleState);
		this.setBlock(world, position.add(0, 2, 9), this.cobbleState);
		this.setBlock(world, position.add(0, 2, 10), this.cobbleState);
		this.setBlock(world, position.add(0, 3, 0), this.cobbleState);
		this.setBlock(world, position.add(0, 3, 1), this.cobbleState);
		this.setBlock(world, position.add(0, 3, 2), this.cobbleState);
		this.setBlock(world, position.add(0, 3, 3), this.cobbleState);
		this.setBlock(world, position.add(0, 3, 4), this.cobbleState);
		this.setBlock(world, position.add(0, 3, 5), this.cobbleState);
		this.setBlock(world, position.add(0, 3, 6), this.cobbleState);
		this.setBlock(world, position.add(0, 3, 7), this.cobbleState);
		this.setBlock(world, position.add(0, 3, 8), this.cobbleState);
		this.setBlock(world, position.add(0, 3, 9), this.cobbleState);
		this.setBlock(world, position.add(0, 3, 10), this.cobbleState);
		this.setBlock(world, position.add(0, 4, 0), this.cobbleState);
		this.setBlock(world, position.add(0, 4, 1), this.cobbleState);
		this.setBlock(world, position.add(0, 4, 2), this.cobbleState);
		this.setBlock(world, position.add(0, 4, 3), this.cobbleState);
		this.setBlock(world, position.add(0, 4, 4), this.cobbleState);
		this.setBlock(world, position.add(0, 4, 5), this.cobbleState);
		this.setBlock(world, position.add(0, 4, 6), this.cobbleState);
		this.setBlock(world, position.add(0, 4, 7), this.cobbleState);
		this.setBlock(world, position.add(0, 4, 8), this.cobbleState);
		this.setBlock(world, position.add(0, 4, 9), this.cobbleState);
		this.setBlock(world, position.add(0, 4, 10), this.cobbleState);
		this.setBlock(world, position.add(0, 5, 0), this.cobbleState);
		this.setBlock(world, position.add(0, 5, 1), this.cobbleState);
		this.setBlock(world, position.add(0, 5, 2), this.cobbleState);
		this.setBlock(world, position.add(0, 5, 3), this.cobbleState);
		this.setBlock(world, position.add(0, 5, 4), this.cobbleState);
		this.setBlock(world, position.add(0, 5, 5), this.cobbleState);
		this.setBlock(world, position.add(0, 5, 6), this.cobbleState);
		this.setBlock(world, position.add(0, 5, 7), this.cobbleState);
		this.setBlock(world, position.add(0, 5, 8), this.cobbleState);
		this.setBlock(world, position.add(0, 5, 9), this.cobbleState);
		this.setBlock(world, position.add(0, 5, 10), this.cobbleState);
		this.setBlock(world, position.add(0, 6, 0), this.cobbleState);
		this.setBlock(world, position.add(0, 6, 1), this.cobbleState);
		this.setBlock(world, position.add(0, 6, 2), this.cobbleState);
		this.setBlock(world, position.add(0, 6, 3), this.cobbleState);
		this.setBlock(world, position.add(0, 6, 4), this.cobbleState);
		this.setBlock(world, position.add(0, 6, 5), this.cobbleState);
		this.setBlock(world, position.add(0, 6, 6), this.cobbleState);
		this.setBlock(world, position.add(0, 6, 7), this.cobbleState);
		this.setBlock(world, position.add(0, 6, 8), this.cobbleState);
		this.setBlock(world, position.add(0, 6, 9), this.cobbleState);
		this.setBlock(world, position.add(0, 6, 10), this.cobbleState);
		this.setBlock(world, position.add(0, 7, 0), this.cobbleState);
		this.setBlock(world, position.add(0, 7, 1), this.cobbleState);
		this.setBlock(world, position.add(0, 7, 2), this.cobbleState);
		this.setBlock(world, position.add(0, 7, 3), this.cobbleState);
		this.setBlock(world, position.add(0, 7, 4), this.cobbleState);
		this.setBlock(world, position.add(0, 7, 5), this.cobbleState);
		this.setBlock(world, position.add(0, 7, 6), this.cobbleState);
		this.setBlock(world, position.add(0, 7, 7), this.cobbleState);
		this.setBlock(world, position.add(0, 7, 8), this.cobbleState);
		this.setBlock(world, position.add(0, 7, 9), this.cobbleState);
		this.setBlock(world, position.add(0, 7, 10), this.cobbleState);
		this.setBlock(world, position.add(0, 8, 0), this.cobbleState);
		this.setBlock(world, position.add(0, 8, 1), this.cobbleState);
		this.setBlock(world, position.add(0, 8, 2), this.cobbleState);
		this.setBlock(world, position.add(0, 8, 3), this.cobbleState);
		this.setBlock(world, position.add(0, 8, 4), this.cobbleState);
		this.setBlock(world, position.add(0, 8, 5), this.cobbleState);
		this.setBlock(world, position.add(0, 8, 6), this.cobbleState);
		this.setBlock(world, position.add(0, 8, 7), this.cobbleState);
		this.setBlock(world, position.add(0, 8, 8), this.cobbleState);
		this.setBlock(world, position.add(0, 8, 9), this.cobbleState);
		this.setBlock(world, position.add(0, 8, 10), this.cobbleState);
		this.setBlock(world, position.add(0, 9, 0), this.cobbleState);
		this.setBlock(world, position.add(0, 9, 1), this.cobbleState);
		this.setBlock(world, position.add(0, 9, 2), this.cobbleState);
		this.setBlock(world, position.add(0, 9, 3), this.cobbleState);
		this.setBlock(world, position.add(0, 9, 4), this.cobbleState);
		this.setBlock(world, position.add(0, 9, 5), this.cobbleState);
		this.setBlock(world, position.add(0, 9, 6), this.cobbleState);
		this.setBlock(world, position.add(0, 9, 7), this.cobbleState);
		this.setBlock(world, position.add(0, 9, 8), this.cobbleState);
		this.setBlock(world, position.add(0, 9, 9), this.cobbleState);
		this.setBlock(world, position.add(0, 9, 10), this.cobbleState);
		this.setBlock(world, position.add(0, 10, 0), this.cobbleState);
		this.setBlock(world, position.add(0, 10, 1), this.cobbleState);
		this.setBlock(world, position.add(0, 10, 2), this.cobbleState);
		this.setBlock(world, position.add(0, 10, 3), this.cobbleState);
		this.setBlock(world, position.add(0, 10, 4), this.cobbleState);
		this.setBlock(world, position.add(0, 10, 5), this.cobbleState);
		this.setBlock(world, position.add(0, 10, 6), this.cobbleState);
		this.setBlock(world, position.add(0, 10, 7), this.cobbleState);
		this.setBlock(world, position.add(0, 10, 8), this.cobbleState);
		this.setBlock(world, position.add(0, 10, 9), this.cobbleState);
		this.setBlock(world, position.add(0, 10, 10), this.cobbleState);
		this.setBlock(world, position.add(0, 11, 0), this.cobbleState);
		this.setBlock(world, position.add(0, 11, 1), this.cobbleState);
		this.setBlock(world, position.add(0, 11, 2), this.cobbleState);
		this.setBlock(world, position.add(0, 11, 3), this.cobbleState);
		this.setBlock(world, position.add(0, 11, 4), this.cobbleState);
		this.setBlock(world, position.add(0, 11, 5), this.cobbleState);
		this.setBlock(world, position.add(0, 11, 6), this.cobbleState);
		this.setBlock(world, position.add(0, 11, 7), this.cobbleState);
		this.setBlock(world, position.add(0, 11, 8), this.cobbleState);
		this.setBlock(world, position.add(0, 11, 9), this.cobbleState);
		this.setBlock(world, position.add(0, 11, 10), this.cobbleState);
		this.setBlock(world, position.add(0, 12, 0), this.cobbleState);
		this.setBlock(world, position.add(0, 12, 1), this.cobbleState);
		this.setBlock(world, position.add(0, 12, 2), this.cobbleState);
		this.setBlock(world, position.add(0, 12, 3), this.cobbleState);
		this.setBlock(world, position.add(0, 12, 4), this.cobbleState);
		this.setBlock(world, position.add(0, 12, 5), this.cobbleState);
		this.setBlock(world, position.add(0, 12, 6), this.cobbleState);
		this.setBlock(world, position.add(0, 12, 7), this.cobbleState);
		this.setBlock(world, position.add(0, 12, 8), this.cobbleState);
		this.setBlock(world, position.add(0, 12, 9), this.cobbleState);
		this.setBlock(world, position.add(0, 12, 10), this.cobbleState);
		this.setBlock(world, position.add(0, 13, 0), this.cobbleState);
		this.setBlock(world, position.add(0, 13, 1), this.bedrockState);
		this.setBlock(world, position.add(0, 13, 2), this.bedrockState);
		this.setBlock(world, position.add(0, 13, 3), this.bedrockState);
		this.setBlock(world, position.add(0, 13, 4), this.bedrockState);
		this.setBlock(world, position.add(0, 13, 5), this.bedrockState);
		this.setBlock(world, position.add(0, 13, 6), this.bedrockState);
		this.setBlock(world, position.add(0, 13, 7), this.bedrockState);
		this.setBlock(world, position.add(0, 13, 8), this.bedrockState);
		this.setBlock(world, position.add(0, 13, 9), this.bedrockState);
		this.setBlock(world, position.add(0, 13, 10), this.cobbleState);
		this.setBlock(world, position.add(0, 14, 0), this.cobbleState);
		this.setBlock(world, position.add(0, 14, 1), this.bedrockState);
		this.setBlock(world, position.add(0, 14, 2), this.bedrockState);
		this.setBlock(world, position.add(0, 14, 3), this.bedrockState);
		this.setBlock(world, position.add(0, 14, 4), this.bedrockState);
		this.setBlock(world, position.add(0, 14, 5), this.bedrockState);
		this.setBlock(world, position.add(0, 14, 6), this.bedrockState);
		this.setBlock(world, position.add(0, 14, 7), this.bedrockState);
		this.setBlock(world, position.add(0, 14, 8), this.bedrockState);
		this.setBlock(world, position.add(0, 14, 9), this.bedrockState);
		this.setBlock(world, position.add(0, 14, 10), this.cobbleState);
		this.setBlock(world, position.add(0, 15, 0), this.cobbleState);
		this.setBlock(world, position.add(0, 15, 1), this.bedrockState);
		this.setBlock(world, position.add(0, 15, 2), this.bedrockState);
		this.setBlock(world, position.add(0, 15, 3), this.bedrockState);
		this.setBlock(world, position.add(0, 15, 4), this.bedrockState);
		this.setBlock(world, position.add(0, 15, 5), this.bedrockState);
		this.setBlock(world, position.add(0, 15, 6), this.bedrockState);
		this.setBlock(world, position.add(0, 15, 7), this.bedrockState);
		this.setBlock(world, position.add(0, 15, 8), this.bedrockState);
		this.setBlock(world, position.add(0, 15, 9), this.bedrockState);
		this.setBlock(world, position.add(0, 15, 10), this.cobbleState);
		this.setBlock(world, position.add(0, 16, 0), this.cobbleState);
		this.setBlock(world, position.add(0, 16, 1), this.bedrockState);
		this.setBlock(world, position.add(0, 16, 2), this.bedrockState);
		this.setBlock(world, position.add(0, 16, 3), this.bedrockState);
		this.setBlock(world, position.add(0, 16, 4), this.bedrockState);
		this.setBlock(world, position.add(0, 16, 5), this.bedrockState);
		this.setBlock(world, position.add(0, 16, 6), this.bedrockState);
		this.setBlock(world, position.add(0, 16, 7), this.bedrockState);
		this.setBlock(world, position.add(0, 16, 8), this.bedrockState);
		this.setBlock(world, position.add(0, 16, 9), this.bedrockState);
		this.setBlock(world, position.add(0, 16, 10), this.cobbleState);
		this.setBlock(world, position.add(0, 17, 0), this.glassState);
		this.setBlock(world, position.add(0, 17, 1), this.glassState);
		this.setBlock(world, position.add(0, 17, 2), this.glassState);
		this.setBlock(world, position.add(0, 17, 3), this.glassState);
		this.setBlock(world, position.add(0, 17, 4), this.glassState);
		this.setBlock(world, position.add(0, 17, 5), this.glassState);
		this.setBlock(world, position.add(0, 17, 6), this.glassState);
		this.setBlock(world, position.add(0, 17, 7), this.glassState);
		this.setBlock(world, position.add(0, 17, 8), this.glassState);
		this.setBlock(world, position.add(0, 17, 9), this.glassState);
		this.setBlock(world, position.add(0, 17, 10), this.glassState);
		this.setBlock(world, position.add(1, 0, 0), this.cobbleState);
		this.setBlock(world, position.add(1, 0, 1), this.cobbleState);
		this.setBlock(world, position.add(1, 0, 2), this.cobbleState);
		this.setBlock(world, position.add(1, 0, 3), this.cobbleState);
		this.setBlock(world, position.add(1, 0, 4), this.cobbleState);
		this.setBlock(world, position.add(1, 0, 5), this.cobbleState);
		this.setBlock(world, position.add(1, 0, 6), this.cobbleState);
		this.setBlock(world, position.add(1, 0, 7), this.stairState);
		this.setBlock(world, position.add(1, 0, 8), this.airState);
		this.setBlock(world, position.add(1, 0, 9), this.airState);
		this.setBlock(world, position.add(1, 0, 10), this.cobbleState);
		this.setBlock(world, position.add(1, 1, 0), this.cobbleState);
		this.setBlock(world, position.add(1, 1, 1), this.cobbleState);
		this.setBlock(world, position.add(1, 1, 2), this.cobbleState);
		this.setBlock(world, position.add(1, 1, 3), this.cobbleState);
		this.setBlock(world, position.add(1, 1, 4), this.cobbleState);
		this.setBlock(world, position.add(1, 1, 5), this.cobbleState);
		this.setBlock(world, position.add(1, 1, 6), this.stairState);
		this.setBlock(world, position.add(1, 1, 7), this.airState);
		this.setBlock(world, position.add(1, 1, 8), this.airState);
		this.setBlock(world, position.add(1, 1, 9), this.airState);
		this.setBlock(world, position.add(1, 1, 10), this.cobbleState);
		this.setBlock(world, position.add(1, 2, 0), this.cobbleState);
		this.setBlock(world, position.add(1, 2, 1), this.cobbleState);
		this.setBlock(world, position.add(1, 2, 2), this.cobbleState);
		this.setBlock(world, position.add(1, 2, 3), this.cobbleState);
		this.setBlock(world, position.add(1, 2, 4), this.cobbleState);
		this.setBlock(world, position.add(1, 2, 5), this.stairState);
		this.setBlock(world, position.add(1, 2, 6), this.airState);
		this.setBlock(world, position.add(1, 2, 7), this.airState);
		this.setBlock(world, position.add(1, 2, 8), this.airState);
		this.setBlock(world, position.add(1, 2, 9), this.airState);
		this.setBlock(world, position.add(1, 2, 10), this.cobbleState);
		this.setBlock(world, position.add(1, 3, 0), this.cobbleState);
		this.setBlock(world, position.add(1, 3, 1), this.cobbleState);
		this.setBlock(world, position.add(1, 3, 2), this.cobbleState);
		this.setBlock(world, position.add(1, 3, 3), this.airState);
		this.setBlock(world, position.add(1, 3, 4), this.airState);
		this.setBlock(world, position.add(1, 3, 5), this.airState);
		this.setBlock(world, position.add(1, 3, 6), this.airState);
		this.setBlock(world, position.add(1, 3, 7), this.airState);
		this.setBlock(world, position.add(1, 3, 8), this.airState);
		this.setBlock(world, position.add(1, 3, 9), this.airState);
		this.setBlock(world, position.add(1, 3, 10), this.cobbleState);
		this.setBlock(world, position.add(1, 4, 0), this.cobbleState);
		this.setBlock(world, position.add(1, 4, 1), this.cobbleState);
		this.setBlock(world, position.add(1, 4, 2), this.cobbleState);
		this.setBlock(world, position.add(1, 4, 3), this.airState);
		this.setBlock(world, position.add(1, 4, 4), this.airState);
		this.setBlock(world, position.add(1, 4, 5), this.airState);
		this.setBlock(world, position.add(1, 4, 6), this.airState);
		this.setBlock(world, position.add(1, 4, 7), this.airState);
		this.setBlock(world, position.add(1, 4, 8), this.airState);
		this.setBlock(world, position.add(1, 4, 9), this.airState);
		this.setBlock(world, position.add(1, 4, 10), this.cobbleState);
		this.setBlock(world, position.add(1, 5, 0), this.cobbleState);
		this.setBlock(world, position.add(1, 5, 1), this.cobbleState);
		this.setBlock(world, position.add(1, 5, 2), this.cobbleState);
		this.setBlock(world, position.add(1, 5, 3), this.airState);
		this.setBlock(world, position.add(1, 5, 4), this.airState);
		this.setBlock(world, position.add(1, 5, 5), this.airState);
		this.setBlock(world, position.add(1, 5, 6), this.airState);
		this.setBlock(world, position.add(1, 5, 7), this.airState);
		this.setBlock(world, position.add(1, 5, 8), this.airState);
		this.setBlock(world, position.add(1, 5, 9), this.airState);
		this.setBlock(world, position.add(1, 5, 10), this.cobbleState);
		this.setBlock(world, position.add(1, 6, 0), this.cobbleState);
		this.setBlock(world, position.add(1, 6, 1), this.cobbleState);
		this.setBlock(world, position.add(1, 6, 2), this.cobbleState);
		this.setBlock(world, position.add(1, 6, 3), this.airState);
		this.setBlock(world, position.add(1, 6, 4), this.airState);
		this.setBlock(world, position.add(1, 6, 5), this.airState);
		this.setBlock(world, position.add(1, 6, 6), this.airState);
		this.setBlock(world, position.add(1, 6, 7), this.airState);
		this.setBlock(world, position.add(1, 6, 8), this.airState);
		this.setBlock(world, position.add(1, 6, 9), this.airState);
		this.setBlock(world, position.add(1, 6, 10), this.cobbleState);
		this.setBlock(world, position.add(1, 7, 0), this.cobbleState);
		this.setBlock(world, position.add(1, 7, 1), this.cobbleState);
		this.setBlock(world, position.add(1, 7, 2), this.cobbleState);
		this.setBlock(world, position.add(1, 7, 3), this.cobbleState);
		this.setBlock(world, position.add(1, 7, 4), this.cobbleState);
		this.setBlock(world, position.add(1, 7, 5), this.cobbleState);
		this.setBlock(world, position.add(1, 7, 6), this.cobbleState);
		this.setBlock(world, position.add(1, 7, 7), this.cobbleState);
		this.setBlock(world, position.add(1, 7, 8), this.cobbleState);
		this.setBlock(world, position.add(1, 7, 9), this.cobbleState);
		this.setBlock(world, position.add(1, 7, 10), this.cobbleState);
		this.setBlock(world, position.add(1, 8, 0), this.cobbleState);
		this.setBlock(world, position.add(1, 8, 1), this.cobbleState);
		this.setBlock(world, position.add(1, 8, 2), this.cobbleState);
		this.setBlock(world, position.add(1, 8, 3), this.airState);
		this.setBlock(world, position.add(1, 8, 4), this.cobbleState);
		this.setBlock(world, position.add(1, 8, 5), this.cobbleState);
		this.setBlock(world, position.add(1, 8, 6), this.cobbleState);
		this.setBlock(world, position.add(1, 8, 7), this.stairState);
		this.setBlock(world, position.add(1, 8, 8), this.airState);
		this.setBlock(world, position.add(1, 8, 9), this.airState);
		this.setBlock(world, position.add(1, 8, 10), this.cobbleState);
		this.setBlock(world, position.add(1, 9, 0), this.cobbleState);
		this.setBlock(world, position.add(1, 9, 1), this.cobbleState);
		this.setBlock(world, position.add(1, 9, 2), this.cobbleState);
		this.setBlock(world, position.add(1, 9, 3), this.cobbleState);
		this.setBlock(world, position.add(1, 9, 4), this.cobbleState);
		this.setBlock(world, position.add(1, 9, 5), this.cobbleState);
		this.setBlock(world, position.add(1, 9, 6), this.stairState);
		this.setBlock(world, position.add(1, 9, 7), this.airState);
		this.setBlock(world, position.add(1, 9, 8), this.airState);
		this.setBlock(world, position.add(1, 9, 9), this.airState);
		this.setBlock(world, position.add(1, 9, 10), this.cobbleState);
		this.setBlock(world, position.add(1, 10, 0), this.cobbleState);
		this.setBlock(world, position.add(1, 10, 1), this.cobbleState);
		this.setBlock(world, position.add(1, 10, 2), this.cobbleState);
		this.setBlock(world, position.add(1, 10, 3), this.cobbleState);
		this.setBlock(world, position.add(1, 10, 4), this.cobbleState);
		this.setBlock(world, position.add(1, 10, 5), this.stairState);
		this.setBlock(world, position.add(1, 10, 6), this.airState);
		this.setBlock(world, position.add(1, 10, 7), this.airState);
		this.setBlock(world, position.add(1, 10, 8), this.airState);
		this.setBlock(world, position.add(1, 10, 9), this.airState);
		this.setBlock(world, position.add(1, 10, 10), this.cobbleState);
		this.setBlock(world, position.add(1, 11, 0), this.cobbleState);
		this.setBlock(world, position.add(1, 11, 1), this.cobbleState);
		this.setBlock(world, position.add(1, 11, 2), this.cobbleState);
		this.setBlock(world, position.add(1, 11, 3), this.cobbleState);
		this.setBlock(world, position.add(1, 11, 4), this.stairState);
		this.setBlock(world, position.add(1, 11, 5), this.airState);
		this.setBlock(world, position.add(1, 11, 6), this.airState);
		this.setBlock(world, position.add(1, 11, 7), this.airState);
		this.setBlock(world, position.add(1, 11, 8), this.airState);
		this.setBlock(world, position.add(1, 11, 9), this.airState);
		this.setBlock(world, position.add(1, 11, 10), this.cobbleState);
		this.setBlock(world, position.add(1, 12, 0), this.cobbleState);
		this.setBlock(world, position.add(1, 12, 1), this.slabState);
		this.setBlock(world, position.add(1, 12, 2), this.slabState);
		this.setBlock(world, position.add(1, 12, 3), this.slabState);
		this.setBlock(world, position.add(1, 12, 4), this.airState);
		this.setBlock(world, position.add(1, 12, 5), this.airState);
		this.setBlock(world, position.add(1, 12, 6), this.airState);
		this.setBlock(world, position.add(1, 12, 7), this.slabState);
		this.setBlock(world, position.add(1, 12, 8), this.slabState);
		this.setBlock(world, position.add(1, 12, 9), this.slabState);
		this.setBlock(world, position.add(1, 12, 10), this.cobbleState);
		this.setBlock(world, position.add(1, 13, 0), this.bedrockState);
		this.setBlock(world, position.add(1, 13, 1), this.airState);
		this.setBlock(world, position.add(1, 13, 2), this.airState);
		this.setBlock(world, position.add(1, 13, 3), this.airState);
		this.setBlock(world, position.add(1, 13, 4), this.airState);
		this.setBlock(world, position.add(1, 13, 5), this.airState);
		this.setBlock(world, position.add(1, 13, 6), this.airState);
		this.setBlock(world, position.add(1, 13, 7), this.airState);
		this.setBlock(world, position.add(1, 13, 8), this.airState);
		this.setBlock(world, position.add(1, 13, 9), this.airState);
		this.setBlock(world, position.add(1, 13, 10), this.bedrockState);
		this.setBlock(world, position.add(1, 14, 0), this.bedrockState);
		this.setBlock(world, position.add(1, 14, 1), this.airState);
		this.setBlock(world, position.add(1, 14, 2), this.airState);
		this.setBlock(world, position.add(1, 14, 3), this.airState);
		this.setBlock(world, position.add(1, 14, 4), this.airState);
		this.setBlock(world, position.add(1, 14, 5), this.airState);
		this.setBlock(world, position.add(1, 14, 6), this.airState);
		this.setBlock(world, position.add(1, 14, 7), this.airState);
		this.setBlock(world, position.add(1, 14, 8), this.airState);
		this.setBlock(world, position.add(1, 14, 9), this.airState);
		this.setBlock(world, position.add(1, 14, 10), this.bedrockState);
		this.setBlock(world, position.add(1, 15, 0), this.bedrockState);
		this.setBlock(world, position.add(1, 15, 1), this.airState);
		this.setBlock(world, position.add(1, 15, 2), this.airState);
		this.setBlock(world, position.add(1, 15, 3), this.airState);
		this.setBlock(world, position.add(1, 15, 4), this.airState);
		this.setBlock(world, position.add(1, 15, 5), this.airState);
		this.setBlock(world, position.add(1, 15, 6), this.airState);
		this.setBlock(world, position.add(1, 15, 7), this.airState);
		this.setBlock(world, position.add(1, 15, 8), this.airState);
		this.setBlock(world, position.add(1, 15, 9), this.airState);
		this.setBlock(world, position.add(1, 15, 10), this.bedrockState);
		this.setBlock(world, position.add(1, 16, 0), this.bedrockState);
		this.setBlock(world, position.add(1, 16, 1), this.airState);
		this.setBlock(world, position.add(1, 16, 2), this.airState);
		this.setBlock(world, position.add(1, 16, 3), this.airState);
		this.setBlock(world, position.add(1, 16, 4), this.airState);
		this.setBlock(world, position.add(1, 16, 5), this.airState);
		this.setBlock(world, position.add(1, 16, 6), this.airState);
		this.setBlock(world, position.add(1, 16, 7), this.airState);
		this.setBlock(world, position.add(1, 16, 8), this.airState);
		this.setBlock(world, position.add(1, 16, 9), this.airState);
		this.setBlock(world, position.add(1, 16, 10), this.bedrockState);
		this.setBlock(world, position.add(1, 17, 0), this.glassState);
		this.setBlock(world, position.add(1, 17, 1), this.glassState);
		this.setBlock(world, position.add(1, 17, 2), this.glassState);
		this.setBlock(world, position.add(1, 17, 3), this.glassState);
		this.setBlock(world, position.add(1, 17, 4), this.glassState);
		this.setBlock(world, position.add(1, 17, 5), this.glassState);
		this.setBlock(world, position.add(1, 17, 6), this.glassState);
		this.setBlock(world, position.add(1, 17, 7), this.glassState);
		this.setBlock(world, position.add(1, 17, 8), this.glassState);
		this.setBlock(world, position.add(1, 17, 9), this.glassState);
		this.setBlock(world, position.add(1, 17, 10), this.glassState);
		this.setBlock(world, position.add(2, 0, 0), this.cobbleState);
		this.setBlock(world, position.add(2, 0, 1), this.cobbleState);
		this.setBlock(world, position.add(2, 0, 2), this.cobbleState);
		this.setBlock(world, position.add(2, 0, 3), this.cobbleState);
		this.setBlock(world, position.add(2, 0, 4), this.cobbleState);
		this.setBlock(world, position.add(2, 0, 5), this.cobbleState);
		this.setBlock(world, position.add(2, 0, 6), this.cobbleState);
		this.setBlock(world, position.add(2, 0, 7), this.cobbleState);
		this.setBlock(world, position.add(2, 0, 8), this.airState);
		this.setBlock(world, position.add(2, 0, 9), this.cobbleState);
		this.setBlock(world, position.add(2, 0, 10), this.cobbleState);
		this.setBlock(world, position.add(2, 1, 0), this.cobbleState);
		this.setBlock(world, position.add(2, 1, 1), this.cobbleState);
		this.setBlock(world, position.add(2, 1, 2), this.cobbleState);
		this.setBlock(world, position.add(2, 1, 3), this.cobbleState);
		this.setBlock(world, position.add(2, 1, 4), this.cobbleState);
		this.setBlock(world, position.add(2, 1, 5), this.cobbleState);
		this.setBlock(world, position.add(2, 1, 6), this.cobbleState);
		this.setBlock(world, position.add(2, 1, 7), this.cobbleState);
		this.setBlock(world, position.add(2, 1, 8), this.airState);
		this.setBlock(world, position.add(2, 1, 9), this.cobbleState);
		this.setBlock(world, position.add(2, 1, 10), this.cobbleState);
		this.setBlock(world, position.add(2, 2, 0), this.cobbleState);
		this.setBlock(world, position.add(2, 2, 1), this.cobbleState);
		this.setBlock(world, position.add(2, 2, 2), this.cobbleState);
		this.setBlock(world, position.add(2, 2, 3), this.cobbleState);
		this.setBlock(world, position.add(2, 2, 4), this.cobbleState);
		this.setBlock(world, position.add(2, 2, 5), this.cobbleState);
		this.setBlock(world, position.add(2, 2, 6), this.cobbleState);
		this.setBlock(world, position.add(2, 2, 7), this.cobbleState);
		this.setBlock(world, position.add(2, 2, 8), this.cobbleState);
		this.setBlock(world, position.add(2, 2, 9), this.cobbleState);
		this.setBlock(world, position.add(2, 2, 10), this.cobbleState);
		this.setBlock(world, position.add(2, 3, 0), this.cobbleState);
		this.setBlock(world, position.add(2, 3, 1), this.cobbleState);
		this.setBlock(world, position.add(2, 3, 2), this.cobbleState);
		this.setBlock(world, position.add(2, 3, 3), this.airState);
		this.setBlock(world, position.add(2, 3, 4), this.cobbleState);
		this.setBlock(world, position.add(2, 3, 5), this.cobbleState);
		this.setBlock(world, position.add(2, 3, 6), this.cobbleState);
		this.setBlock(world, position.add(2, 3, 7), this.cobbleState);
		this.setBlock(world, position.add(2, 3, 8), this.cobbleState);
		this.setBlock(world, position.add(2, 3, 9), this.cobbleState);
		this.setBlock(world, position.add(2, 3, 10), this.cobbleState);
		this.setBlock(world, position.add(2, 4, 0), this.cobbleState);
		this.setBlock(world, position.add(2, 4, 1), this.cobbleState);
		this.setBlock(world, position.add(2, 4, 2), this.cobbleState);
		this.setBlock(world, position.add(2, 4, 3), this.airState);
		this.setBlock(world, position.add(2, 4, 4), this.cobbleState);
		this.setBlock(world, position.add(2, 4, 5), this.cobbleState);
		this.setBlock(world, position.add(2, 4, 6), this.cobbleState);
		this.setBlock(world, position.add(2, 4, 7), this.cobbleState);
		this.setBlock(world, position.add(2, 4, 8), this.cobbleState);
		this.setBlock(world, position.add(2, 4, 9), this.cobbleState);
		this.setBlock(world, position.add(2, 4, 10), this.cobbleState);
		this.setBlock(world, position.add(2, 5, 0), this.cobbleState);
		this.setBlock(world, position.add(2, 5, 1), this.cobbleState);
		this.setBlock(world, position.add(2, 5, 2), this.cobbleState);
		this.setBlock(world, position.add(2, 5, 3), this.airState);
		this.setBlock(world, position.add(2, 5, 4), this.cobbleState);
		this.setBlock(world, position.add(2, 5, 5), this.cobbleState);
		this.setBlock(world, position.add(2, 5, 6), this.cobbleState);
		this.setBlock(world, position.add(2, 5, 7), this.cobbleState);
		this.setBlock(world, position.add(2, 5, 8), this.cobbleState);
		this.setBlock(world, position.add(2, 5, 9), this.cobbleState);
		this.setBlock(world, position.add(2, 5, 10), this.cobbleState);
		this.setBlock(world, position.add(2, 6, 0), this.cobbleState);
		this.setBlock(world, position.add(2, 6, 1), this.cobbleState);
		this.setBlock(world, position.add(2, 6, 2), this.cobbleState);
		this.setBlock(world, position.add(2, 6, 3), this.cobbleState);
		this.setBlock(world, position.add(2, 6, 4), this.cobbleState);
		this.setBlock(world, position.add(2, 6, 5), this.cobbleState);
		this.setBlock(world, position.add(2, 6, 6), this.cobbleState);
		this.setBlock(world, position.add(2, 6, 7), this.cobbleState);
		this.setBlock(world, position.add(2, 6, 8), this.cobbleState);
		this.setBlock(world, position.add(2, 6, 9), this.cobbleState);
		this.setBlock(world, position.add(2, 6, 10), this.cobbleState);
		this.setBlock(world, position.add(2, 7, 0), this.cobbleState);
		this.setBlock(world, position.add(2, 7, 1), this.cobbleState);
		this.setBlock(world, position.add(2, 7, 2), this.cobbleState);
		this.setBlock(world, position.add(2, 7, 3), this.cobbleState);
		this.setBlock(world, position.add(2, 7, 4), this.cobbleState);
		this.setBlock(world, position.add(2, 7, 5), this.cobbleState);
		this.setBlock(world, position.add(2, 7, 6), this.cobbleState);
		this.setBlock(world, position.add(2, 7, 7), this.cobbleState);
		this.setBlock(world, position.add(2, 7, 8), this.cobbleState);
		this.setBlock(world, position.add(2, 7, 9), this.cobbleState);
		this.setBlock(world, position.add(2, 7, 10), this.cobbleState);
		this.setBlock(world, position.add(2, 8, 0), this.cobbleState);
		this.setBlock(world, position.add(2, 8, 1), this.cobbleState);
		this.setBlock(world, position.add(2, 8, 2), this.cobbleState);
		this.setBlock(world, position.add(2, 8, 3), this.cobbleState);
		this.setBlock(world, position.add(2, 8, 4), this.airState);
		this.setBlock(world, position.add(2, 8, 5), this.cobbleState);
		this.setBlock(world, position.add(2, 8, 6), this.cobbleState);
		this.setBlock(world, position.add(2, 8, 7), this.cobbleState);
		this.setBlock(world, position.add(2, 8, 8), this.ironBarState);
		this.setBlock(world, position.add(2, 8, 9), this.cobbleState);
		this.setBlock(world, position.add(2, 8, 10), this.cobbleState);
		this.setBlock(world, position.add(2, 9, 0), this.cobbleState);
		this.setBlock(world, position.add(2, 9, 1), this.cobbleState);
		this.setBlock(world, position.add(2, 9, 2), this.cobbleState);
		this.setBlock(world, position.add(2, 9, 3), this.cobbleState);
		this.setBlock(world, position.add(2, 9, 4), this.airState);
		this.setBlock(world, position.add(2, 9, 5), this.cobbleState);
		this.setBlock(world, position.add(2, 9, 6), this.cobbleState);
		this.setBlock(world, position.add(2, 9, 7), this.cobbleState);
		this.setBlock(world, position.add(2, 9, 8), this.ironBarState);
		this.setBlock(world, position.add(2, 9, 9), this.cobbleState);
		this.setBlock(world, position.add(2, 9, 10), this.cobbleState);
		this.setBlock(world, position.add(2, 10, 0), this.cobbleState);
		this.setBlock(world, position.add(2, 10, 1), this.cobbleState);
		this.setBlock(world, position.add(2, 10, 2), this.cobbleState);
		this.setBlock(world, position.add(2, 10, 3), this.cobbleState);
		this.setBlock(world, position.add(2, 10, 4), this.cobbleState);
		this.setBlock(world, position.add(2, 10, 5), this.cobbleState);
		this.setBlock(world, position.add(2, 10, 6), this.cobbleState);
		this.setBlock(world, position.add(2, 10, 7), this.cobbleState);
		this.setBlock(world, position.add(2, 10, 8), this.cobbleState);
		this.setBlock(world, position.add(2, 10, 9), this.cobbleState);
		this.setBlock(world, position.add(2, 10, 10), this.cobbleState);
		this.setBlock(world, position.add(2, 11, 0), this.cobbleState);
		this.setBlock(world, position.add(2, 11, 1), this.cobbleState);
		this.setBlock(world, position.add(2, 11, 2), this.cobbleState);
		this.setBlock(world, position.add(2, 11, 3), this.cobbleState);
		this.setBlock(world, position.add(2, 11, 4), this.cobbleState);
		this.setBlock(world, position.add(2, 11, 5), this.cobbleState);
		this.setBlock(world, position.add(2, 11, 6), this.cobbleState);
		this.setBlock(world, position.add(2, 11, 7), this.cobbleState);
		this.setBlock(world, position.add(2, 11, 8), this.cobbleState);
		this.setBlock(world, position.add(2, 11, 9), this.cobbleState);
		this.setBlock(world, position.add(2, 11, 10), this.cobbleState);
		this.setBlock(world, position.add(2, 12, 0), this.cobbleState);
		this.setBlock(world, position.add(2, 12, 1), this.slabState);
		this.setBlock(world, position.add(2, 12, 2), this.slabState);
		this.setBlock(world, position.add(2, 12, 3), this.slabState);
		this.setBlock(world, position.add(2, 12, 4), this.slabState);
		this.setBlock(world, position.add(2, 12, 5), this.slabState);
		this.setBlock(world, position.add(2, 12, 6), this.slabState);
		this.setBlock(world, position.add(2, 12, 7), this.slabState);
		this.setBlock(world, position.add(2, 12, 8), this.slabState);
		this.setBlock(world, position.add(2, 12, 9), this.slabState);
		this.setBlock(world, position.add(2, 12, 10), this.cobbleState);
		this.setBlock(world, position.add(2, 13, 0), this.bedrockState);
		this.setBlock(world, position.add(2, 13, 1), this.airState);
		this.setBlock(world, position.add(2, 13, 2), this.airState);
		this.setBlock(world, position.add(2, 13, 3), this.airState);
		this.setBlock(world, position.add(2, 13, 4), this.airState);
		this.setBlock(world, position.add(2, 13, 5), this.airState);
		this.setBlock(world, position.add(2, 13, 6), this.airState);
		this.setBlock(world, position.add(2, 13, 7), this.airState);
		this.setBlock(world, position.add(2, 13, 8), this.airState);
		this.setBlock(world, position.add(2, 13, 9), this.airState);
		this.setBlock(world, position.add(2, 13, 10), this.bedrockState);
		this.setBlock(world, position.add(2, 14, 0), this.bedrockState);
		this.setBlock(world, position.add(2, 14, 1), this.airState);
		this.setBlock(world, position.add(2, 14, 2), this.airState);
		this.setBlock(world, position.add(2, 14, 3), this.airState);
		this.setBlock(world, position.add(2, 14, 4), this.airState);
		this.setBlock(world, position.add(2, 14, 5), this.airState);
		this.setBlock(world, position.add(2, 14, 6), this.airState);
		this.setBlock(world, position.add(2, 14, 7), this.airState);
		this.setBlock(world, position.add(2, 14, 8), this.airState);
		this.setBlock(world, position.add(2, 14, 9), this.airState);
		this.setBlock(world, position.add(2, 14, 10), this.bedrockState);
		this.setBlock(world, position.add(2, 15, 0), this.bedrockState);
		this.setBlock(world, position.add(2, 15, 1), this.airState);
		this.setBlock(world, position.add(2, 15, 2), this.airState);
		this.setBlock(world, position.add(2, 15, 3), this.airState);
		this.setBlock(world, position.add(2, 15, 4), this.airState);
		this.setBlock(world, position.add(2, 15, 5), this.airState);
		this.setBlock(world, position.add(2, 15, 6), this.airState);
		this.setBlock(world, position.add(2, 15, 7), this.airState);
		this.setBlock(world, position.add(2, 15, 8), this.airState);
		this.setBlock(world, position.add(2, 15, 9), this.airState);
		this.setBlock(world, position.add(2, 15, 10), this.bedrockState);
		this.setBlock(world, position.add(2, 16, 0), this.bedrockState);
		this.setBlock(world, position.add(2, 16, 1), this.airState);
		this.setBlock(world, position.add(2, 16, 2), this.airState);
		this.setBlock(world, position.add(2, 16, 3), this.airState);
		this.setBlock(world, position.add(2, 16, 4), this.airState);
		this.setBlock(world, position.add(2, 16, 5), this.airState);
		this.setBlock(world, position.add(2, 16, 6), this.airState);
		this.setBlock(world, position.add(2, 16, 7), this.airState);
		this.setBlock(world, position.add(2, 16, 8), this.airState);
		this.setBlock(world, position.add(2, 16, 9), this.airState);
		this.setBlock(world, position.add(2, 16, 10), this.bedrockState);
		this.setBlock(world, position.add(2, 17, 0), this.glassState);
		this.setBlock(world, position.add(2, 17, 1), this.glassState);
		this.setBlock(world, position.add(2, 17, 2), this.glassState);
		this.setBlock(world, position.add(2, 17, 3), this.glassState);
		this.setBlock(world, position.add(2, 17, 4), this.glassState);
		this.setBlock(world, position.add(2, 17, 5), this.glassState);
		this.setBlock(world, position.add(2, 17, 6), this.glassState);
		this.setBlock(world, position.add(2, 17, 7), this.glassState);
		this.setBlock(world, position.add(2, 17, 8), this.glassState);
		this.setBlock(world, position.add(2, 17, 9), this.glassState);
		this.setBlock(world, position.add(2, 17, 10), this.glassState);
		this.setBlock(world, position.add(3, 0, 0), this.cobbleState);
		this.setBlock(world, position.add(3, 0, 1), this.airState);
		this.setBlock(world, position.add(3, 0, 2), this.airState);
		this.setBlock(world, position.add(3, 0, 3), this.airState);
		this.setBlock(world, position.add(3, 0, 4), this.airState);
		this.setBlock(world, position.add(3, 0, 5), this.airState);
		this.setBlock(world, position.add(3, 0, 6), this.airState);
		this.setBlock(world, position.add(3, 0, 7), this.airState);
		this.setBlock(world, position.add(3, 0, 8), this.airState);
		this.setBlock(world, position.add(3, 0, 9), this.airState);
		this.setBlock(world, position.add(3, 0, 10), this.cobbleState);
		this.setBlock(world, position.add(3, 1, 0), this.cobbleState);
		this.setBlock(world, position.add(3, 1, 1), this.airState);
		this.setBlock(world, position.add(3, 1, 2), this.airState);
		this.setBlock(world, position.add(3, 1, 3), this.airState);
		this.setBlock(world, position.add(3, 1, 4), this.airState);
		this.setBlock(world, position.add(3, 1, 5), this.airState);
		this.setBlock(world, position.add(3, 1, 6), this.airState);
		this.setBlock(world, position.add(3, 1, 7), this.airState);
		this.setBlock(world, position.add(3, 1, 8), this.airState);
		this.setBlock(world, position.add(3, 1, 9), this.airState);
		this.setBlock(world, position.add(3, 1, 10), this.cobbleState);
		this.setBlock(world, position.add(3, 2, 0), this.cobbleState);
		this.setBlock(world, position.add(3, 2, 1), this.airState);
		this.setBlock(world, position.add(3, 2, 2), this.airState);
		this.setBlock(world, position.add(3, 2, 3), this.airState);
		this.setBlock(world, position.add(3, 2, 4), this.airState);
		this.setBlock(world, position.add(3, 2, 5), this.airState);
		this.setBlock(world, position.add(3, 2, 6), this.airState);
		this.setBlock(world, position.add(3, 2, 7), this.airState);
		this.setBlock(world, position.add(3, 2, 8), this.airState);
		this.setBlock(world, position.add(3, 2, 9), this.airState);
		this.setBlock(world, position.add(3, 2, 10), this.cobbleState);
		this.setBlock(world, position.add(3, 3, 0), this.cobbleState);
		this.setBlock(world, position.add(3, 3, 1), this.slabState);
		this.setBlock(world, position.add(3, 3, 2), this.slabState);
		this.setBlock(world, position.add(3, 3, 3), this.slabState);
		this.setBlock(world, position.add(3, 3, 4), this.slabState);
		this.setBlock(world, position.add(3, 3, 5), this.slabState);
		this.setBlock(world, position.add(3, 3, 6), this.slabState);
		this.setBlock(world, position.add(3, 3, 7), this.slabState);
		this.setBlock(world, position.add(3, 3, 8), this.slabState);
		this.setBlock(world, position.add(3, 3, 9), this.slabState);
		this.setBlock(world, position.add(3, 3, 10), this.cobbleState);
		this.setBlock(world, position.add(3, 4, 0), this.cobbleState);
		this.setBlock(world, position.add(3, 4, 1), this.airState);
		this.setBlock(world, position.add(3, 4, 2), this.airState);
		this.setBlock(world, position.add(3, 4, 3), this.airState);
		this.setBlock(world, position.add(3, 4, 4), this.airState);
		this.setBlock(world, position.add(3, 4, 5), this.airState);
		this.setBlock(world, position.add(3, 4, 6), this.airState);
		this.setBlock(world, position.add(3, 4, 7), this.airState);
		this.setBlock(world, position.add(3, 4, 8), this.airState);
		this.setBlock(world, position.add(3, 4, 9), this.airState);
		this.setBlock(world, position.add(3, 4, 10), this.cobbleState);
		this.setBlock(world, position.add(3, 5, 0), this.cobbleState);
		this.setBlock(world, position.add(3, 5, 1), this.airState);
		this.setBlock(world, position.add(3, 5, 2), this.airState);
		this.setBlock(world, position.add(3, 5, 3), this.airState);
		this.setBlock(world, position.add(3, 5, 4), this.airState);
		this.setBlock(world, position.add(3, 5, 5), this.airState);
		this.setBlock(world, position.add(3, 5, 6), this.airState);
		this.setBlock(world, position.add(3, 5, 7), this.airState);
		this.setBlock(world, position.add(3, 5, 8), this.airState);
		this.setBlock(world, position.add(3, 5, 9), this.airState);
		this.setBlock(world, position.add(3, 5, 10), this.cobbleState);
		this.setBlock(world, position.add(3, 6, 0), this.cobbleState);
		this.setBlock(world, position.add(3, 6, 1), this.airState);
		this.setBlock(world, position.add(3, 6, 2), this.airState);
		this.setBlock(world, position.add(3, 6, 3), this.airState);
		this.setBlock(world, position.add(3, 6, 4), this.airState);
		this.setBlock(world, position.add(3, 6, 5), this.airState);
		this.setBlock(world, position.add(3, 6, 6), this.airState);
		this.setBlock(world, position.add(3, 6, 7), this.airState);
		this.setBlock(world, position.add(3, 6, 8), this.airState);
		this.setBlock(world, position.add(3, 6, 9), this.airState);
		this.setBlock(world, position.add(3, 6, 10), this.cobbleState);
		this.setBlock(world, position.add(3, 7, 0), this.cobbleState);
		this.setBlock(world, position.add(3, 7, 1), this.slabState);
		this.setBlock(world, position.add(3, 7, 2), this.slabState);
		this.setBlock(world, position.add(3, 7, 3), this.slabState);
		this.setBlock(world, position.add(3, 7, 4), this.slabState);
		this.setBlock(world, position.add(3, 7, 5), this.slabState);
		this.setBlock(world, position.add(3, 7, 6), this.slabState);
		this.setBlock(world, position.add(3, 7, 7), this.slabState);
		this.setBlock(world, position.add(3, 7, 8), this.slabState);
		this.setBlock(world, position.add(3, 7, 9), this.airState);
		this.setBlock(world, position.add(3, 7, 10), this.cobbleState);
		this.setBlock(world, position.add(3, 8, 0), this.cobbleState);
		this.setBlock(world, position.add(3, 8, 1), this.airState);
		this.setBlock(world, position.add(3, 8, 2), this.airState);
		this.setBlock(world, position.add(3, 8, 3), this.airState);
		this.setBlock(world, position.add(3, 8, 4), this.airState);
		this.setBlock(world, position.add(3, 8, 5), this.airState);
		this.setBlock(world, position.add(3, 8, 6), this.airState);
		this.setBlock(world, position.add(3, 8, 7), this.airState);
		this.setBlock(world, position.add(3, 8, 8), this.airState);
		this.setBlock(world, position.add(3, 8, 9), this.airState);
		this.setBlock(world, position.add(3, 8, 10), this.cobbleState);
		this.setBlock(world, position.add(3, 9, 0), this.cobbleState);
		this.setBlock(world, position.add(3, 9, 1), this.airState);
		this.setBlock(world, position.add(3, 9, 2), this.airState);
		this.setBlock(world, position.add(3, 9, 3), this.airState);
		this.setBlock(world, position.add(3, 9, 4), this.airState);
		this.setBlock(world, position.add(3, 9, 5), this.airState);
		this.setBlock(world, position.add(3, 9, 6), this.airState);
		this.setBlock(world, position.add(3, 9, 7), this.airState);
		this.setBlock(world, position.add(3, 9, 8), this.airState);
		this.setBlock(world, position.add(3, 9, 9), this.airState);
		this.setBlock(world, position.add(3, 9, 10), this.cobbleState);
		this.setBlock(world, position.add(3, 10, 0), this.cobbleState);
		this.setBlock(world, position.add(3, 10, 1), this.airState);
		this.setBlock(world, position.add(3, 10, 2), this.airState);
		this.setBlock(world, position.add(3, 10, 3), this.airState);
		this.setBlock(world, position.add(3, 10, 4), this.airState);
		this.setBlock(world, position.add(3, 10, 5), this.airState);
		this.setBlock(world, position.add(3, 10, 6), this.airState);
		this.setBlock(world, position.add(3, 10, 7), this.airState);
		this.setBlock(world, position.add(3, 10, 8), this.airState);
		this.setBlock(world, position.add(3, 10, 9), this.airState);
		this.setBlock(world, position.add(3, 10, 10), this.cobbleState);
		this.setBlock(world, position.add(3, 11, 0), this.cobbleState);
		this.setBlock(world, position.add(3, 11, 1), this.airState);
		this.setBlock(world, position.add(3, 11, 2), this.airState);
		this.setBlock(world, position.add(3, 11, 3), this.airState);
		this.setBlock(world, position.add(3, 11, 4), this.airState);
		this.setBlock(world, position.add(3, 11, 5), this.airState);
		this.setBlock(world, position.add(3, 11, 6), this.airState);
		this.setBlock(world, position.add(3, 11, 7), this.airState);
		this.setBlock(world, position.add(3, 11, 8), this.airState);
		this.setBlock(world, position.add(3, 11, 9), this.airState);
		this.setBlock(world, position.add(3, 11, 10), this.cobbleState);
		this.setBlock(world, position.add(3, 12, 0), this.cobbleState);
		this.setBlock(world, position.add(3, 12, 1), this.slabState);
		this.setBlock(world, position.add(3, 12, 2), this.slabState);
		this.setBlock(world, position.add(3, 12, 3), this.slabState);
		this.setBlock(world, position.add(3, 12, 4), this.slabState);
		this.setBlock(world, position.add(3, 12, 5), this.slabState);
		this.setBlock(world, position.add(3, 12, 6), this.slabState);
		this.setBlock(world, position.add(3, 12, 7), this.slabState);
		this.setBlock(world, position.add(3, 12, 8), this.slabState);
		this.setBlock(world, position.add(3, 12, 9), this.slabState);
		this.setBlock(world, position.add(3, 12, 10), this.cobbleState);
		this.setBlock(world, position.add(3, 13, 0), this.bedrockState);
		this.setBlock(world, position.add(3, 13, 1), this.airState);
		this.setBlock(world, position.add(3, 13, 2), this.airState);
		this.setBlock(world, position.add(3, 13, 3), this.airState);
		this.setBlock(world, position.add(3, 13, 4), this.airState);
		this.setBlock(world, position.add(3, 13, 5), this.airState);
		this.setBlock(world, position.add(3, 13, 6), this.airState);
		this.setBlock(world, position.add(3, 13, 7), this.airState);
		this.setBlock(world, position.add(3, 13, 8), this.airState);
		this.setBlock(world, position.add(3, 13, 9), this.airState);
		this.setBlock(world, position.add(3, 13, 10), this.bedrockState);
		this.setBlock(world, position.add(3, 14, 0), this.bedrockState);
		this.setBlock(world, position.add(3, 14, 1), this.airState);
		this.setBlock(world, position.add(3, 14, 2), this.airState);
		this.setBlock(world, position.add(3, 14, 3), this.airState);
		this.setBlock(world, position.add(3, 14, 4), this.airState);
		this.setBlock(world, position.add(3, 14, 5), this.airState);
		this.setBlock(world, position.add(3, 14, 6), this.airState);
		this.setBlock(world, position.add(3, 14, 7), this.airState);
		this.setBlock(world, position.add(3, 14, 8), this.airState);
		this.setBlock(world, position.add(3, 14, 9), this.airState);
		this.setBlock(world, position.add(3, 14, 10), this.bedrockState);
		this.setBlock(world, position.add(3, 15, 0), this.bedrockState);
		this.setBlock(world, position.add(3, 15, 1), this.airState);
		this.setBlock(world, position.add(3, 15, 2), this.airState);
		this.setBlock(world, position.add(3, 15, 3), this.airState);
		this.setBlock(world, position.add(3, 15, 4), this.airState);
		this.setBlock(world, position.add(3, 15, 5), this.airState);
		this.setBlock(world, position.add(3, 15, 6), this.airState);
		this.setBlock(world, position.add(3, 15, 7), this.airState);
		this.setBlock(world, position.add(3, 15, 8), this.airState);
		this.setBlock(world, position.add(3, 15, 9), this.airState);
		this.setBlock(world, position.add(3, 15, 10), this.bedrockState);
		this.setBlock(world, position.add(3, 16, 0), this.bedrockState);
		this.setBlock(world, position.add(3, 16, 1), this.airState);
		this.setBlock(world, position.add(3, 16, 2), this.airState);
		this.setBlock(world, position.add(3, 16, 3), this.airState);
		this.setBlock(world, position.add(3, 16, 4), this.airState);
		this.setBlock(world, position.add(3, 16, 5), this.airState);
		this.setBlock(world, position.add(3, 16, 6), this.airState);
		this.setBlock(world, position.add(3, 16, 7), this.airState);
		this.setBlock(world, position.add(3, 16, 8), this.airState);
		this.setBlock(world, position.add(3, 16, 9), this.airState);
		this.setBlock(world, position.add(3, 16, 10), this.bedrockState);
		this.setBlock(world, position.add(3, 17, 0), this.glassState);
		this.setBlock(world, position.add(3, 17, 1), this.glassState);
		this.setBlock(world, position.add(3, 17, 2), this.glassState);
		this.setBlock(world, position.add(3, 17, 3), this.glassState);
		this.setBlock(world, position.add(3, 17, 4), this.glassState);
		this.setBlock(world, position.add(3, 17, 5), this.glassState);
		this.setBlock(world, position.add(3, 17, 6), this.glassState);
		this.setBlock(world, position.add(3, 17, 7), this.glassState);
		this.setBlock(world, position.add(3, 17, 8), this.glassState);
		this.setBlock(world, position.add(3, 17, 9), this.glassState);
		this.setBlock(world, position.add(3, 17, 10), this.glassState);
		this.setBlock(world, position.add(4, 0, 0), this.cobbleState);
		this.setBlock(world, position.add(4, 0, 1), this.airState);
		this.setBlock(world, position.add(4, 0, 2), this.airState);
		this.setBlock(world, position.add(4, 0, 3), this.airState);
		this.setBlock(world, position.add(4, 0, 4), this.airState);
		this.setBlock(world, position.add(4, 0, 5), this.airState);
		this.setBlock(world, position.add(4, 0, 6), this.airState);
		this.setBlock(world, position.add(4, 0, 7), this.airState);
		this.setBlock(world, position.add(4, 0, 8), this.airState);
		this.setBlock(world, position.add(4, 0, 9), this.airState);
		this.setBlock(world, position.add(4, 0, 10), this.cobbleState);
		this.setBlock(world, position.add(4, 1, 0), this.cobbleState);
		this.setBlock(world, position.add(4, 1, 1), this.airState);
		this.setBlock(world, position.add(4, 1, 2), this.airState);
		this.setBlock(world, position.add(4, 1, 3), this.airState);
		this.setBlock(world, position.add(4, 1, 4), this.airState);
		this.setBlock(world, position.add(4, 1, 5), this.airState);
		this.setBlock(world, position.add(4, 1, 6), this.airState);
		this.setBlock(world, position.add(4, 1, 7), this.airState);
		this.setBlock(world, position.add(4, 1, 8), this.airState);
		this.setBlock(world, position.add(4, 1, 9), this.airState);
		this.setBlock(world, position.add(4, 1, 10), this.cobbleState);
		this.setBlock(world, position.add(4, 2, 0), this.cobbleState);
		this.setBlock(world, position.add(4, 2, 1), this.airState);
		this.setBlock(world, position.add(4, 2, 2), this.airState);
		this.setBlock(world, position.add(4, 2, 3), this.airState);
		this.setBlock(world, position.add(4, 2, 4), this.airState);
		this.setBlock(world, position.add(4, 2, 5), this.airState);
		this.setBlock(world, position.add(4, 2, 6), this.airState);
		this.setBlock(world, position.add(4, 2, 7), this.airState);
		this.setBlock(world, position.add(4, 2, 8), this.airState);
		this.setBlock(world, position.add(4, 2, 9), this.airState);
		this.setBlock(world, position.add(4, 2, 10), this.cobbleState);
		this.setBlock(world, position.add(4, 3, 0), this.cobbleState);
		this.setBlock(world, position.add(4, 3, 1), this.slabState);
		this.setBlock(world, position.add(4, 3, 2), this.slabState);
		this.setBlock(world, position.add(4, 3, 3), this.airState);
		this.setBlock(world, position.add(4, 3, 4), this.slabState);
		this.setBlock(world, position.add(4, 3, 5), this.slabState);
		this.setBlock(world, position.add(4, 3, 6), this.slabState);
		this.setBlock(world, position.add(4, 3, 7), this.slabState);
		this.setBlock(world, position.add(4, 3, 8), this.slabState);
		this.setBlock(world, position.add(4, 3, 9), this.airState);
		this.setBlock(world, position.add(4, 3, 10), this.cobbleState);
		this.setBlock(world, position.add(4, 4, 0), this.cobbleState);
		this.setBlock(world, position.add(4, 4, 1), this.airState);
		this.setBlock(world, position.add(4, 4, 2), this.airState);
		this.setBlock(world, position.add(4, 4, 3), this.airState);
		this.setBlock(world, position.add(4, 4, 4), this.airState);
		this.setBlock(world, position.add(4, 4, 5), this.airState);
		this.setBlock(world, position.add(4, 4, 6), this.airState);
		this.setBlock(world, position.add(4, 4, 7), this.airState);
		this.setBlock(world, position.add(4, 4, 8), this.airState);
		this.setBlock(world, position.add(4, 4, 9), this.airState);
		this.setBlock(world, position.add(4, 4, 10), this.cobbleState);
		this.setBlock(world, position.add(4, 5, 0), this.cobbleState);
		this.setBlock(world, position.add(4, 5, 1), this.airState);
		this.setBlock(world, position.add(4, 5, 2), this.airState);
		this.setBlock(world, position.add(4, 5, 3), this.airState);
		this.setBlock(world, position.add(4, 5, 4), this.airState);
		this.setBlock(world, position.add(4, 5, 5), this.airState);
		this.setBlock(world, position.add(4, 5, 6), this.airState);
		this.setBlock(world, position.add(4, 5, 7), this.airState);
		this.setBlock(world, position.add(4, 5, 8), this.airState);
		this.setBlock(world, position.add(4, 5, 9), this.airState);
		this.setBlock(world, position.add(4, 5, 10), this.cobbleState);
		this.setBlock(world, position.add(4, 6, 0), this.cobbleState);
		this.setBlock(world, position.add(4, 6, 1), this.airState);
		this.setBlock(world, position.add(4, 6, 2), this.airState);
		this.setBlock(world, position.add(4, 6, 3), this.airState);
		this.setBlock(world, position.add(4, 6, 4), this.airState);
		this.setBlock(world, position.add(4, 6, 5), this.airState);
		this.setBlock(world, position.add(4, 6, 6), this.airState);
		this.setBlock(world, position.add(4, 6, 7), this.airState);
		this.setBlock(world, position.add(4, 6, 8), this.airState);
		this.setBlock(world, position.add(4, 6, 9), this.airState);
		this.setBlock(world, position.add(4, 6, 10), this.cobbleState);
		this.setBlock(world, position.add(4, 7, 0), this.cobbleState);
		this.setBlock(world, position.add(4, 7, 1), this.slabState);
		this.setBlock(world, position.add(4, 7, 2), this.slabState);
		this.setBlock(world, position.add(4, 7, 3), this.slabState);
		this.setBlock(world, position.add(4, 7, 4), this.slabState);
		this.setBlock(world, position.add(4, 7, 5), this.airState);
		this.setBlock(world, position.add(4, 7, 6), this.slabState);
		this.setBlock(world, position.add(4, 7, 7), this.slabState);
		this.setBlock(world, position.add(4, 7, 8), this.slabState);
		this.setBlock(world, position.add(4, 7, 9), this.slabState);
		this.setBlock(world, position.add(4, 7, 10), this.cobbleState);
		this.setBlock(world, position.add(4, 8, 0), this.cobbleState);
		this.setBlock(world, position.add(4, 8, 1), this.airState);
		this.setBlock(world, position.add(4, 8, 3), this.airState);
		this.setBlock(world, position.add(4, 8, 4), this.cobbleState);
		this.setBlock(world, position.add(4, 8, 5), this.cobbleState);
		this.setBlock(world, position.add(4, 8, 6), this.airState);
		this.setBlock(world, position.add(4, 8, 8), this.airState);
		this.setBlock(world, position.add(4, 8, 9), this.airState);
		this.setBlock(world, position.add(4, 8, 10), this.cobbleState);
		this.setBlock(world, position.add(4, 9, 0), this.cobbleState);
		this.setBlock(world, position.add(4, 9, 1), this.airState);
		this.setBlock(world, position.add(4, 9, 2), this.airState);
		this.setBlock(world, position.add(4, 9, 3), this.airState);
		this.setBlock(world, position.add(4, 9, 6), this.airState);
		this.setBlock(world, position.add(4, 9, 7), this.airState);
		this.setBlock(world, position.add(4, 9, 8), this.airState);
		this.setBlock(world, position.add(4, 9, 9), this.airState);
		this.setBlock(world, position.add(4, 9, 10), this.cobbleState);
		this.setBlock(world, position.add(4, 10, 0), this.cobbleState);
		this.setBlock(world, position.add(4, 10, 1), this.airState);
		this.setBlock(world, position.add(4, 10, 2), this.airState);
		this.setBlock(world, position.add(4, 10, 3), this.airState);
		this.setBlock(world, position.add(4, 10, 4), this.airState);
		this.setBlock(world, position.add(4, 10, 5), this.airState);
		this.setBlock(world, position.add(4, 10, 6), this.airState);
		this.setBlock(world, position.add(4, 10, 7), this.airState);
		this.setBlock(world, position.add(4, 10, 8), this.airState);
		this.setBlock(world, position.add(4, 10, 9), this.airState);
		this.setBlock(world, position.add(4, 10, 10), this.cobbleState);
		this.setBlock(world, position.add(4, 11, 0), this.cobbleState);
		this.setBlock(world, position.add(4, 11, 1), this.airState);
		this.setBlock(world, position.add(4, 11, 2), this.airState);
		this.setBlock(world, position.add(4, 11, 3), this.airState);
		this.setBlock(world, position.add(4, 11, 4), this.airState);
		this.setBlock(world, position.add(4, 11, 5), this.airState);
		this.setBlock(world, position.add(4, 11, 6), this.airState);
		this.setBlock(world, position.add(4, 11, 7), this.airState);
		this.setBlock(world, position.add(4, 11, 8), this.airState);
		this.setBlock(world, position.add(4, 11, 9), this.airState);
		this.setBlock(world, position.add(4, 11, 10), this.cobbleState);
		this.setBlock(world, position.add(4, 12, 0), this.cobbleState);
		this.setBlock(world, position.add(4, 12, 1), this.slabState);
		this.setBlock(world, position.add(4, 12, 2), this.slabState);
		this.setBlock(world, position.add(4, 12, 3), this.slabState);
		this.setBlock(world, position.add(4, 12, 4), this.slabState);
		this.setBlock(world, position.add(4, 12, 5), this.slabState);
		this.setBlock(world, position.add(4, 12, 6), this.slabState);
		this.setBlock(world, position.add(4, 12, 7), this.slabState);
		this.setBlock(world, position.add(4, 12, 8), this.slabState);
		this.setBlock(world, position.add(4, 12, 9), this.slabState);
		this.setBlock(world, position.add(4, 12, 10), this.cobbleState);
		this.setBlock(world, position.add(4, 13, 0), this.bedrockState);
		this.setBlock(world, position.add(4, 13, 1), this.airState);
		this.setBlock(world, position.add(4, 13, 2), this.airState);
		this.setBlock(world, position.add(4, 13, 3), this.airState);
		this.setBlock(world, position.add(4, 13, 4), this.airState);
		this.setBlock(world, position.add(4, 13, 5), this.airState);
		this.setBlock(world, position.add(4, 13, 6), this.airState);
		this.setBlock(world, position.add(4, 13, 7), this.airState);
		this.setBlock(world, position.add(4, 13, 8), this.airState);
		this.setBlock(world, position.add(4, 13, 9), this.airState);
		this.setBlock(world, position.add(4, 13, 10), this.bedrockState);
		this.setBlock(world, position.add(4, 14, 0), this.bedrockState);
		this.setBlock(world, position.add(4, 14, 1), this.airState);
		this.setBlock(world, position.add(4, 14, 2), this.airState);
		this.setBlock(world, position.add(4, 14, 3), this.airState);
		this.setBlock(world, position.add(4, 14, 4), this.airState);
		this.setBlock(world, position.add(4, 14, 5), this.airState);
		this.setBlock(world, position.add(4, 14, 6), this.airState);
		this.setBlock(world, position.add(4, 14, 7), this.airState);
		this.setBlock(world, position.add(4, 14, 8), this.airState);
		this.setBlock(world, position.add(4, 14, 9), this.airState);
		this.setBlock(world, position.add(4, 14, 10), this.bedrockState);
		this.setBlock(world, position.add(4, 15, 0), this.bedrockState);
		this.setBlock(world, position.add(4, 15, 1), this.airState);
		this.setBlock(world, position.add(4, 15, 2), this.airState);
		this.setBlock(world, position.add(4, 15, 3), this.airState);
		this.setBlock(world, position.add(4, 15, 4), this.airState);
		this.setBlock(world, position.add(4, 15, 5), this.airState);
		this.setBlock(world, position.add(4, 15, 6), this.airState);
		this.setBlock(world, position.add(4, 15, 7), this.airState);
		this.setBlock(world, position.add(4, 15, 8), this.airState);
		this.setBlock(world, position.add(4, 15, 9), this.airState);
		this.setBlock(world, position.add(4, 15, 10), this.bedrockState);
		this.setBlock(world, position.add(4, 16, 0), this.bedrockState);
		this.setBlock(world, position.add(4, 16, 1), this.airState);
		this.setBlock(world, position.add(4, 16, 2), this.airState);
		this.setBlock(world, position.add(4, 16, 3), this.airState);
		this.setBlock(world, position.add(4, 16, 4), this.airState);
		this.setBlock(world, position.add(4, 16, 5), this.airState);
		this.setBlock(world, position.add(4, 16, 6), this.airState);
		this.setBlock(world, position.add(4, 16, 7), this.airState);
		this.setBlock(world, position.add(4, 16, 8), this.airState);
		this.setBlock(world, position.add(4, 16, 9), this.airState);
		this.setBlock(world, position.add(4, 16, 10), this.bedrockState);
		this.setBlock(world, position.add(4, 17, 0), this.glassState);
		this.setBlock(world, position.add(4, 17, 1), this.glassState);
		this.setBlock(world, position.add(4, 17, 2), this.glassState);
		this.setBlock(world, position.add(4, 17, 3), this.glassState);
		this.setBlock(world, position.add(4, 17, 4), this.glassState);
		this.setBlock(world, position.add(4, 17, 5), this.glassState);
		this.setBlock(world, position.add(4, 17, 6), this.glassState);
		this.setBlock(world, position.add(4, 17, 7), this.glassState);
		this.setBlock(world, position.add(4, 17, 8), this.glassState);
		this.setBlock(world, position.add(4, 17, 9), this.glassState);
		this.setBlock(world, position.add(4, 17, 10), this.glassState);
		this.setBlock(world, position.add(5, 0, 0), this.cobbleState);
		this.setBlock(world, position.add(5, 0, 1), this.airState);
		this.setBlock(world, position.add(5, 0, 2), this.airState);
		this.setBlock(world, position.add(5, 0, 3), this.airState);
		this.setBlock(world, position.add(5, 0, 4), this.airState);
		this.setBlock(world, position.add(5, 0, 5), this.airState);
		this.setBlock(world, position.add(5, 0, 6), this.airState);
		this.setBlock(world, position.add(5, 0, 7), this.airState);
		this.setBlock(world, position.add(5, 0, 8), this.airState);
		this.setBlock(world, position.add(5, 0, 9), this.airState);
		this.setBlock(world, position.add(5, 0, 10), this.cobbleState);
		this.setBlock(world, position.add(5, 1, 0), this.airState);
		this.setBlock(world, position.add(5, 1, 1), this.airState);
		this.setBlock(world, position.add(5, 1, 2), this.airState);
		this.setBlock(world, position.add(5, 1, 3), this.airState);
		this.setBlock(world, position.add(5, 1, 4), this.airState);
		this.setBlock(world, position.add(5, 1, 5), this.airState);
		this.setBlock(world, position.add(5, 1, 6), this.airState);
		this.setBlock(world, position.add(5, 1, 7), this.airState);
		this.setBlock(world, position.add(5, 1, 8), this.airState);
		this.setBlock(world, position.add(5, 1, 9), this.airState);
		this.setBlock(world, position.add(5, 1, 10), this.airState);
		this.setBlock(world, position.add(5, 2, 0), this.airState);
		this.setBlock(world, position.add(5, 2, 1), this.airState);
		this.setBlock(world, position.add(5, 2, 2), this.airState);
		this.setBlock(world, position.add(5, 2, 3), this.airState);
		this.setBlock(world, position.add(5, 2, 4), this.airState);
		this.setBlock(world, position.add(5, 2, 5), this.airState);
		this.setBlock(world, position.add(5, 2, 6), this.airState);
		this.setBlock(world, position.add(5, 2, 7), this.airState);
		this.setBlock(world, position.add(5, 2, 8), this.airState);
		this.setBlock(world, position.add(5, 2, 9), this.airState);
		this.setBlock(world, position.add(5, 2, 10), this.airState);
		this.setBlock(world, position.add(5, 3, 0), this.cobbleState);
		this.setBlock(world, position.add(5, 3, 1), this.slabState);
		this.setBlock(world, position.add(5, 3, 2), this.slabState);
		this.setBlock(world, position.add(5, 3, 3), this.slabState);
		this.setBlock(world, position.add(5, 3, 4), this.slabState);
		this.setBlock(world, position.add(5, 3, 5), this.slabState);
		this.setBlock(world, position.add(5, 3, 6), this.slabState);
		this.setBlock(world, position.add(5, 3, 7), this.slabState);
		this.setBlock(world, position.add(5, 3, 8), this.slabState);
		this.setBlock(world, position.add(5, 3, 9), this.slabState);
		this.setBlock(world, position.add(5, 3, 10), this.cobbleState);
		this.setBlock(world, position.add(5, 4, 0), this.cobbleState);
		this.setBlock(world, position.add(5, 4, 1), this.airState);
		this.setBlock(world, position.add(5, 4, 2), this.airState);
		this.setBlock(world, position.add(5, 4, 3), this.airState);
		this.setBlock(world, position.add(5, 4, 4), this.airState);
		this.setBlock(world, position.add(5, 4, 5), this.airState);
		this.setBlock(world, position.add(5, 4, 6), this.airState);
		this.setBlock(world, position.add(5, 4, 7), this.airState);
		this.setBlock(world, position.add(5, 4, 8), this.airState);
		this.setBlock(world, position.add(5, 4, 9), this.airState);
		this.setBlock(world, position.add(5, 4, 10), this.cobbleState);
		this.setBlock(world, position.add(5, 5, 0), this.cobbleState);
		this.setBlock(world, position.add(5, 5, 1), this.airState);
		this.setBlock(world, position.add(5, 5, 2), this.airState);
		this.setBlock(world, position.add(5, 5, 3), this.airState);
		this.setBlock(world, position.add(5, 5, 4), this.airState);
		this.setBlock(world, position.add(5, 5, 5), this.airState);
		this.setBlock(world, position.add(5, 5, 6), this.airState);
		this.setBlock(world, position.add(5, 5, 7), this.airState);
		this.setBlock(world, position.add(5, 5, 8), this.airState);
		this.setBlock(world, position.add(5, 5, 9), this.airState);
		this.setBlock(world, position.add(5, 5, 10), this.cobbleState);
		this.setBlock(world, position.add(5, 6, 0), this.cobbleState);
		this.setBlock(world, position.add(5, 6, 1), this.airState);
		this.setBlock(world, position.add(5, 6, 2), this.airState);
		this.setBlock(world, position.add(5, 6, 3), this.airState);
		this.setBlock(world, position.add(5, 6, 4), this.airState);
		this.setBlock(world, position.add(5, 6, 5), this.airState);
		this.setBlock(world, position.add(5, 6, 6), this.airState);
		this.setBlock(world, position.add(5, 6, 7), this.airState);
		this.setBlock(world, position.add(5, 6, 8), this.airState);
		this.setBlock(world, position.add(5, 6, 9), this.airState);
		this.setBlock(world, position.add(5, 6, 10), this.cobbleState);
		this.setBlock(world, position.add(5, 7, 0), this.cobbleState);
		this.setBlock(world, position.add(5, 7, 1), this.slabState);
		this.setBlock(world, position.add(5, 7, 2), this.slabState);
		this.setBlock(world, position.add(5, 7, 3), this.slabState);
		this.setBlock(world, position.add(5, 7, 4), this.slabState);
		this.setBlock(world, position.add(5, 7, 5), this.slabState);
		this.setBlock(world, position.add(5, 7, 6), this.slabState);
		this.setBlock(world, position.add(5, 7, 7), this.airState);
		this.setBlock(world, position.add(5, 7, 8), this.slabState);
		this.setBlock(world, position.add(5, 7, 9), this.slabState);
		this.setBlock(world, position.add(5, 7, 10), this.cobbleState);
		this.setBlock(world, position.add(5, 8, 0), this.cobbleState);
		this.setBlock(world, position.add(5, 8, 1), this.airState);
		this.setBlock(world, position.add(5, 8, 2), this.airState);
		this.setBlock(world, position.add(5, 8, 3), this.airState);
		this.setBlock(world, position.add(5, 8, 4), this.airState);
		this.setBlock(world, position.add(5, 8, 5), this.airState);
		this.setBlock(world, position.add(5, 8, 6), this.airState);
		this.setBlock(world, position.add(5, 8, 7), this.airState);
		this.setBlock(world, position.add(5, 8, 8), this.airState);
		this.setBlock(world, position.add(5, 8, 9), this.airState);
		this.setBlock(world, position.add(5, 8, 10), this.cobbleState);
		this.setBlock(world, position.add(5, 9, 0), this.cobbleState);
		this.setBlock(world, position.add(5, 9, 1), this.airState);
		this.setBlock(world, position.add(5, 9, 2), this.airState);
		this.setBlock(world, position.add(5, 9, 3), this.airState);
		this.setBlock(world, position.add(5, 9, 4), this.airState);
		this.setBlock(world, position.add(5, 9, 5), this.airState);
		this.setBlock(world, position.add(5, 9, 6), this.airState);
		this.setBlock(world, position.add(5, 9, 7), this.airState);
		this.setBlock(world, position.add(5, 9, 8), this.airState);
		this.setBlock(world, position.add(5, 9, 9), this.airState);
		this.setBlock(world, position.add(5, 9, 10), this.cobbleState);
		this.setBlock(world, position.add(5, 10, 0), this.cobbleState);
		this.setBlock(world, position.add(5, 10, 1), this.airState);
		this.setBlock(world, position.add(5, 10, 2), this.airState);
		this.setBlock(world, position.add(5, 10, 3), this.airState);
		this.setBlock(world, position.add(5, 10, 4), this.airState);
		this.setBlock(world, position.add(5, 10, 5), this.airState);
		this.setBlock(world, position.add(5, 10, 6), this.airState);
		this.setBlock(world, position.add(5, 10, 7), this.airState);
		this.setBlock(world, position.add(5, 10, 8), this.airState);
		this.setBlock(world, position.add(5, 10, 9), this.airState);
		this.setBlock(world, position.add(5, 10, 10), this.cobbleState);
		this.setBlock(world, position.add(5, 11, 0), this.cobbleState);
		this.setBlock(world, position.add(5, 11, 1), this.airState);
		this.setBlock(world, position.add(5, 11, 2), this.airState);
		this.setBlock(world, position.add(5, 11, 3), this.airState);
		this.setBlock(world, position.add(5, 11, 4), this.airState);
		this.setBlock(world, position.add(5, 11, 5), this.airState);
		this.setBlock(world, position.add(5, 11, 6), this.airState);
		this.setBlock(world, position.add(5, 11, 7), this.airState);
		this.setBlock(world, position.add(5, 11, 8), this.airState);
		this.setBlock(world, position.add(5, 11, 9), this.airState);
		this.setBlock(world, position.add(5, 11, 10), this.cobbleState);
		this.setBlock(world, position.add(5, 12, 0), this.cobbleState);
		this.setBlock(world, position.add(5, 12, 1), this.slabState);
		this.setBlock(world, position.add(5, 12, 2), this.slabState);
		this.setBlock(world, position.add(5, 12, 3), this.slabState);
		this.setBlock(world, position.add(5, 12, 4), this.slabState);
		this.setBlock(world, position.add(5, 12, 5), this.slabState);
		this.setBlock(world, position.add(5, 12, 6), this.slabState);
		this.setBlock(world, position.add(5, 12, 7), this.slabState);
		this.setBlock(world, position.add(5, 12, 8), this.slabState);
		this.setBlock(world, position.add(5, 12, 9), this.slabState);
		this.setBlock(world, position.add(5, 12, 10), this.cobbleState);
		this.setBlock(world, position.add(5, 13, 0), this.bedrockState);
		this.setBlock(world, position.add(5, 13, 1), this.airState);
		this.setBlock(world, position.add(5, 13, 2), this.airState);
		this.setBlock(world, position.add(5, 13, 3), this.airState);
		this.setBlock(world, position.add(5, 13, 4), this.airState);
		this.setBlock(world, position.add(5, 13, 5), this.airState);
		this.setBlock(world, position.add(5, 13, 6), this.airState);
		this.setBlock(world, position.add(5, 13, 7), this.airState);
		this.setBlock(world, position.add(5, 13, 8), this.airState);
		this.setBlock(world, position.add(5, 13, 9), this.airState);
		this.setBlock(world, position.add(5, 13, 10), this.bedrockState);
		this.setBlock(world, position.add(5, 14, 0), this.bedrockState);
		this.setBlock(world, position.add(5, 14, 1), this.airState);
		this.setBlock(world, position.add(5, 14, 2), this.airState);
		this.setBlock(world, position.add(5, 14, 3), this.airState);
		this.setBlock(world, position.add(5, 14, 4), this.airState);
		this.setBlock(world, position.add(5, 14, 5), this.airState);
		this.setBlock(world, position.add(5, 14, 6), this.airState);
		this.setBlock(world, position.add(5, 14, 7), this.airState);
		this.setBlock(world, position.add(5, 14, 8), this.airState);
		this.setBlock(world, position.add(5, 14, 9), this.airState);
		this.setBlock(world, position.add(5, 14, 10), this.bedrockState);
		this.setBlock(world, position.add(5, 15, 0), this.bedrockState);
		this.setBlock(world, position.add(5, 15, 1), this.airState);
		this.setBlock(world, position.add(5, 15, 2), this.airState);
		this.setBlock(world, position.add(5, 15, 3), this.airState);
		this.setBlock(world, position.add(5, 15, 4), this.airState);
		this.setBlock(world, position.add(5, 15, 5), this.airState);
		this.setBlock(world, position.add(5, 15, 6), this.airState);
		this.setBlock(world, position.add(5, 15, 7), this.airState);
		this.setBlock(world, position.add(5, 15, 8), this.airState);
		this.setBlock(world, position.add(5, 15, 9), this.airState);
		this.setBlock(world, position.add(5, 15, 10), this.bedrockState);
		this.setBlock(world, position.add(5, 16, 0), this.bedrockState);
		this.setBlock(world, position.add(5, 16, 1), this.airState);
		this.setBlock(world, position.add(5, 16, 2), this.airState);
		this.setBlock(world, position.add(5, 16, 3), this.airState);
		this.setBlock(world, position.add(5, 16, 4), this.airState);
		this.setBlock(world, position.add(5, 16, 5), this.airState);
		this.setBlock(world, position.add(5, 16, 6), this.airState);
		this.setBlock(world, position.add(5, 16, 7), this.airState);
		this.setBlock(world, position.add(5, 16, 8), this.airState);
		this.setBlock(world, position.add(5, 16, 9), this.airState);
		this.setBlock(world, position.add(5, 16, 10), this.bedrockState);
		this.setBlock(world, position.add(5, 17, 0), this.glassState);
		this.setBlock(world, position.add(5, 17, 1), this.glassState);
		this.setBlock(world, position.add(5, 17, 2), this.glassState);
		this.setBlock(world, position.add(5, 17, 3), this.glassState);
		this.setBlock(world, position.add(5, 17, 4), this.glassState);
		this.setBlock(world, position.add(5, 17, 5), this.glassState);
		this.setBlock(world, position.add(5, 17, 6), this.glassState);
		this.setBlock(world, position.add(5, 17, 7), this.glassState);
		this.setBlock(world, position.add(5, 17, 8), this.glassState);
		this.setBlock(world, position.add(5, 17, 9), this.glassState);
		this.setBlock(world, position.add(5, 17, 10), this.glassState);
		this.setBlock(world, position.add(6, 0, 0), this.cobbleState);
		this.setBlock(world, position.add(6, 0, 1), this.airState);
		this.setBlock(world, position.add(6, 0, 2), this.airState);
		this.setBlock(world, position.add(6, 0, 3), this.airState);
		this.setBlock(world, position.add(6, 0, 4), this.airState);
		this.setBlock(world, position.add(6, 0, 5), this.airState);
		this.setBlock(world, position.add(6, 0, 6), this.airState);
		this.setBlock(world, position.add(6, 0, 7), this.airState);
		this.setBlock(world, position.add(6, 0, 8), this.airState);
		this.setBlock(world, position.add(6, 0, 9), this.airState);
		this.setBlock(world, position.add(6, 0, 10), this.cobbleState);
		this.setBlock(world, position.add(6, 1, 0), this.airState);
		this.setBlock(world, position.add(6, 1, 1), this.airState);
		this.setBlock(world, position.add(6, 1, 2), this.airState);
		this.setBlock(world, position.add(6, 1, 3), this.airState);
		this.setBlock(world, position.add(6, 1, 4), this.airState);
		this.setBlock(world, position.add(6, 1, 5), this.airState);
		this.setBlock(world, position.add(6, 1, 6), this.airState);
		this.setBlock(world, position.add(6, 1, 7), this.airState);
		this.setBlock(world, position.add(6, 1, 8), this.airState);
		this.setBlock(world, position.add(6, 1, 9), this.airState);
		this.setBlock(world, position.add(6, 1, 10), this.airState);
		this.setBlock(world, position.add(6, 2, 0), this.airState);
		this.setBlock(world, position.add(6, 2, 1), this.airState);
		this.setBlock(world, position.add(6, 2, 2), this.airState);
		this.setBlock(world, position.add(6, 2, 3), this.airState);
		this.setBlock(world, position.add(6, 2, 4), this.airState);
		this.setBlock(world, position.add(6, 2, 5), this.airState);
		this.setBlock(world, position.add(6, 2, 6), this.airState);
		this.setBlock(world, position.add(6, 2, 7), this.airState);
		this.setBlock(world, position.add(6, 2, 8), this.airState);
		this.setBlock(world, position.add(6, 2, 9), this.airState);
		this.setBlock(world, position.add(6, 2, 10), this.airState);
		this.setBlock(world, position.add(6, 3, 0), this.cobbleState);
		this.setBlock(world, position.add(6, 3, 1), this.slabState);
		this.setBlock(world, position.add(6, 3, 2), this.slabState);
		this.setBlock(world, position.add(6, 3, 3), this.airState);
		this.setBlock(world, position.add(6, 3, 4), this.slabState);
		this.setBlock(world, position.add(6, 3, 5), this.slabState);
		this.setBlock(world, position.add(6, 3, 6), this.airState);
		this.setBlock(world, position.add(6, 3, 7), this.slabState);
		this.setBlock(world, position.add(6, 3, 8), this.slabState);
		this.setBlock(world, position.add(6, 3, 9), this.slabState);
		this.setBlock(world, position.add(6, 3, 10), this.cobbleState);
		this.setBlock(world, position.add(6, 4, 0), this.cobbleState);
		this.setBlock(world, position.add(6, 4, 1), this.airState);
		this.setBlock(world, position.add(6, 4, 2), this.airState);
		this.setBlock(world, position.add(6, 4, 3), this.airState);
		this.setBlock(world, position.add(6, 4, 4), this.airState);
		this.setBlock(world, position.add(6, 4, 5), this.airState);
		this.setBlock(world, position.add(6, 4, 6), this.airState);
		this.setBlock(world, position.add(6, 4, 7), this.airState);
		this.setBlock(world, position.add(6, 4, 8), this.airState);
		this.setBlock(world, position.add(6, 4, 9), this.airState);
		this.setBlock(world, position.add(6, 4, 10), this.cobbleState);
		this.setBlock(world, position.add(6, 5, 0), this.cobbleState);
		this.setBlock(world, position.add(6, 5, 1), this.airState);
		this.setBlock(world, position.add(6, 5, 2), this.airState);
		this.setBlock(world, position.add(6, 5, 3), this.airState);
		this.setBlock(world, position.add(6, 5, 4), this.airState);
		this.setBlock(world, position.add(6, 5, 5), this.airState);
		this.setBlock(world, position.add(6, 5, 6), this.airState);
		this.setBlock(world, position.add(6, 5, 7), this.airState);
		this.setBlock(world, position.add(6, 5, 8), this.airState);
		this.setBlock(world, position.add(6, 5, 9), this.airState);
		this.setBlock(world, position.add(6, 5, 10), this.cobbleState);
		this.setBlock(world, position.add(6, 6, 0), this.cobbleState);
		this.setBlock(world, position.add(6, 6, 1), this.airState);
		this.setBlock(world, position.add(6, 6, 2), this.airState);
		this.setBlock(world, position.add(6, 6, 3), this.airState);
		this.setBlock(world, position.add(6, 6, 4), this.airState);
		this.setBlock(world, position.add(6, 6, 5), this.airState);
		this.setBlock(world, position.add(6, 6, 6), this.airState);
		this.setBlock(world, position.add(6, 6, 7), this.airState);
		this.setBlock(world, position.add(6, 6, 8), this.airState);
		this.setBlock(world, position.add(6, 6, 9), this.airState);
		this.setBlock(world, position.add(6, 6, 10), this.cobbleState);
		this.setBlock(world, position.add(6, 7, 0), this.cobbleState);
		this.setBlock(world, position.add(6, 7, 1), this.slabState);
		this.setBlock(world, position.add(6, 7, 2), this.airState);
		this.setBlock(world, position.add(6, 7, 3), this.slabState);
		this.setBlock(world, position.add(6, 7, 4), this.slabState);
		this.setBlock(world, position.add(6, 7, 5), this.slabState);
		this.setBlock(world, position.add(6, 7, 6), this.slabState);
		this.setBlock(world, position.add(6, 7, 7), this.slabState);
		this.setBlock(world, position.add(6, 7, 8), this.slabState);
		this.setBlock(world, position.add(6, 7, 9), this.slabState);
		this.setBlock(world, position.add(6, 7, 10), this.cobbleState);
		this.setBlock(world, position.add(6, 8, 0), this.cobbleState);
		this.setBlock(world, position.add(6, 8, 1), this.airState);
		this.setBlock(world, position.add(6, 8, 2), this.airState);
		this.setBlock(world, position.add(6, 8, 3), this.airState);
		this.setBlock(world, position.add(6, 8, 4), this.airState);
		this.setBlock(world, position.add(6, 8, 5), this.airState);
		this.setBlock(world, position.add(6, 8, 6), this.airState);
		this.setBlock(world, position.add(6, 8, 7), this.airState);
		this.setBlock(world, position.add(6, 8, 8), this.airState);
		this.setBlock(world, position.add(6, 8, 9), this.airState);
		this.setBlock(world, position.add(6, 8, 10), this.cobbleState);
		this.setBlock(world, position.add(6, 9, 0), this.cobbleState);
		this.setBlock(world, position.add(6, 9, 1), this.airState);
		this.setBlock(world, position.add(6, 9, 2), this.airState);
		this.setBlock(world, position.add(6, 9, 3), this.airState);
		this.setBlock(world, position.add(6, 9, 4), this.airState);
		this.setBlock(world, position.add(6, 9, 5), this.airState);
		this.setBlock(world, position.add(6, 9, 6), this.airState);
		this.setBlock(world, position.add(6, 9, 7), this.airState);
		this.setBlock(world, position.add(6, 9, 8), this.airState);
		this.setBlock(world, position.add(6, 9, 9), this.airState);
		this.setBlock(world, position.add(6, 9, 10), this.cobbleState);
		this.setBlock(world, position.add(6, 10, 0), this.cobbleState);
		this.setBlock(world, position.add(6, 10, 1), this.airState);
		this.setBlock(world, position.add(6, 10, 2), this.airState);
		this.setBlock(world, position.add(6, 10, 3), this.airState);
		this.setBlock(world, position.add(6, 10, 4), this.airState);
		this.setBlock(world, position.add(6, 10, 5), this.airState);
		this.setBlock(world, position.add(6, 10, 6), this.airState);
		this.setBlock(world, position.add(6, 10, 7), this.airState);
		this.setBlock(world, position.add(6, 10, 8), this.airState);
		this.setBlock(world, position.add(6, 10, 9), this.airState);
		this.setBlock(world, position.add(6, 10, 10), this.cobbleState);
		this.setBlock(world, position.add(6, 11, 0), this.cobbleState);
		this.setBlock(world, position.add(6, 11, 1), this.airState);
		this.setBlock(world, position.add(6, 11, 2), this.airState);
		this.setBlock(world, position.add(6, 11, 3), this.airState);
		this.setBlock(world, position.add(6, 11, 4), this.airState);
		this.setBlock(world, position.add(6, 11, 5), this.airState);
		this.setBlock(world, position.add(6, 11, 6), this.airState);
		this.setBlock(world, position.add(6, 11, 7), this.airState);
		this.setBlock(world, position.add(6, 11, 8), this.airState);
		this.setBlock(world, position.add(6, 11, 9), this.airState);
		this.setBlock(world, position.add(6, 11, 10), this.cobbleState);
		this.setBlock(world, position.add(6, 12, 0), this.cobbleState);
		this.setBlock(world, position.add(6, 12, 1), this.slabState);
		this.setBlock(world, position.add(6, 12, 2), this.slabState);
		this.setBlock(world, position.add(6, 12, 3), this.slabState);
		this.setBlock(world, position.add(6, 12, 4), this.slabState);
		this.setBlock(world, position.add(6, 12, 5), this.slabState);
		this.setBlock(world, position.add(6, 12, 6), this.slabState);
		this.setBlock(world, position.add(6, 12, 7), this.slabState);
		this.setBlock(world, position.add(6, 12, 8), this.slabState);
		this.setBlock(world, position.add(6, 12, 9), this.slabState);
		this.setBlock(world, position.add(6, 12, 10), this.cobbleState);
		this.setBlock(world, position.add(6, 13, 0), this.bedrockState);
		this.setBlock(world, position.add(6, 13, 1), this.airState);
		this.setBlock(world, position.add(6, 13, 2), this.airState);
		this.setBlock(world, position.add(6, 13, 3), this.airState);
		this.setBlock(world, position.add(6, 13, 4), this.airState);
		this.setBlock(world, position.add(6, 13, 5), this.airState);
		this.setBlock(world, position.add(6, 13, 6), this.airState);
		this.setBlock(world, position.add(6, 13, 7), this.airState);
		this.setBlock(world, position.add(6, 13, 8), this.airState);
		this.setBlock(world, position.add(6, 13, 9), this.airState);
		this.setBlock(world, position.add(6, 13, 10), this.bedrockState);
		this.setBlock(world, position.add(6, 14, 0), this.bedrockState);
		this.setBlock(world, position.add(6, 14, 1), this.airState);
		this.setBlock(world, position.add(6, 14, 2), this.airState);
		this.setBlock(world, position.add(6, 14, 3), this.airState);
		this.setBlock(world, position.add(6, 14, 4), this.airState);
		this.setBlock(world, position.add(6, 14, 5), this.airState);
		this.setBlock(world, position.add(6, 14, 6), this.airState);
		this.setBlock(world, position.add(6, 14, 7), this.airState);
		this.setBlock(world, position.add(6, 14, 8), this.airState);
		this.setBlock(world, position.add(6, 14, 9), this.airState);
		this.setBlock(world, position.add(6, 14, 10), this.bedrockState);
		this.setBlock(world, position.add(6, 15, 0), this.bedrockState);
		this.setBlock(world, position.add(6, 15, 1), this.airState);
		this.setBlock(world, position.add(6, 15, 2), this.airState);
		this.setBlock(world, position.add(6, 15, 3), this.airState);
		this.setBlock(world, position.add(6, 15, 4), this.airState);
		this.setBlock(world, position.add(6, 15, 5), this.airState);
		this.setBlock(world, position.add(6, 15, 6), this.airState);
		this.setBlock(world, position.add(6, 15, 7), this.airState);
		this.setBlock(world, position.add(6, 15, 8), this.airState);
		this.setBlock(world, position.add(6, 15, 9), this.airState);
		this.setBlock(world, position.add(6, 15, 10), this.bedrockState);
		this.setBlock(world, position.add(6, 16, 0), this.bedrockState);
		this.setBlock(world, position.add(6, 16, 1), this.airState);
		this.setBlock(world, position.add(6, 16, 2), this.airState);
		this.setBlock(world, position.add(6, 16, 3), this.airState);
		this.setBlock(world, position.add(6, 16, 4), this.airState);
		this.setBlock(world, position.add(6, 16, 5), this.airState);
		this.setBlock(world, position.add(6, 16, 6), this.airState);
		this.setBlock(world, position.add(6, 16, 7), this.airState);
		this.setBlock(world, position.add(6, 16, 8), this.airState);
		this.setBlock(world, position.add(6, 16, 9), this.airState);
		this.setBlock(world, position.add(6, 16, 10), this.bedrockState);
		this.setBlock(world, position.add(6, 17, 0), this.glassState);
		this.setBlock(world, position.add(6, 17, 1), this.glassState);
		this.setBlock(world, position.add(6, 17, 2), this.glassState);
		this.setBlock(world, position.add(6, 17, 3), this.glassState);
		this.setBlock(world, position.add(6, 17, 4), this.glassState);
		this.setBlock(world, position.add(6, 17, 5), this.glassState);
		this.setBlock(world, position.add(6, 17, 6), this.glassState);
		this.setBlock(world, position.add(6, 17, 7), this.glassState);
		this.setBlock(world, position.add(6, 17, 8), this.glassState);
		this.setBlock(world, position.add(6, 17, 9), this.glassState);
		this.setBlock(world, position.add(6, 17, 10), this.glassState);
		this.setBlock(world, position.add(7, 0, 0), this.cobbleState);
		this.setBlock(world, position.add(7, 0, 1), this.airState);
		this.setBlock(world, position.add(7, 0, 2), this.airState);
		this.setBlock(world, position.add(7, 0, 9), this.airState);
		this.setBlock(world, position.add(7, 0, 4), this.airState);
		this.setBlock(world, position.add(7, 0, 5), this.cobbleState);
		this.setBlock(world, position.add(7, 0, 6), this.cobbleState);
		this.setBlock(world, position.add(7, 0, 7), this.airState);
		this.setBlock(world, position.add(7, 0, 9), this.airState);
		this.setBlock(world, position.add(7, 0, 10), this.cobbleState);
		this.setBlock(world, position.add(7, 1, 0), this.cobbleState);
		this.setBlock(world, position.add(7, 1, 1), this.airState);
		this.setBlock(world, position.add(7, 1, 2), this.airState);
		this.setBlock(world, position.add(7, 1, 3), this.airState);
		this.setBlock(world, position.add(7, 1, 4), this.airState);
		this.setBlock(world, position.add(7, 1, 7), this.airState);
		this.setBlock(world, position.add(7, 1, 8), this.airState);
		this.setBlock(world, position.add(7, 1, 9), this.airState);
		this.setBlock(world, position.add(7, 1, 10), this.cobbleState);
		this.setBlock(world, position.add(7, 2, 0), this.cobbleState);
		this.setBlock(world, position.add(7, 2, 1), this.airState);
		this.setBlock(world, position.add(7, 2, 2), this.airState);
		this.setBlock(world, position.add(7, 2, 3), this.airState);
		this.setBlock(world, position.add(7, 2, 4), this.airState);
		this.setBlock(world, position.add(7, 2, 5), this.airState);
		this.setBlock(world, position.add(7, 2, 6), this.airState);
		this.setBlock(world, position.add(7, 2, 7), this.airState);
		this.setBlock(world, position.add(7, 2, 8), this.airState);
		this.setBlock(world, position.add(7, 2, 9), this.airState);
		this.setBlock(world, position.add(7, 2, 10), this.cobbleState);
		this.setBlock(world, position.add(7, 3, 0), this.cobbleState);
		this.setBlock(world, position.add(7, 3, 1), this.slabState);
		this.setBlock(world, position.add(7, 3, 2), this.slabState);
		this.setBlock(world, position.add(7, 3, 3), this.slabState);
		this.setBlock(world, position.add(7, 3, 4), this.slabState);
		this.setBlock(world, position.add(7, 3, 5), this.slabState);
		this.setBlock(world, position.add(7, 3, 6), this.slabState);
		this.setBlock(world, position.add(7, 3, 7), this.slabState);
		this.setBlock(world, position.add(7, 3, 8), this.slabState);
		this.setBlock(world, position.add(7, 3, 9), this.slabState);
		this.setBlock(world, position.add(7, 3, 10), this.cobbleState);
		this.setBlock(world, position.add(7, 4, 0), this.cobbleState);
		this.setBlock(world, position.add(7, 4, 1), this.airState);
		this.setBlock(world, position.add(7, 4, 3), this.airState);
		this.setBlock(world, position.add(7, 4, 4), this.airState);
		this.setBlock(world, position.add(7, 4, 5), this.cobbleState);
		this.setBlock(world, position.add(7, 4, 6), this.cobbleState);
		this.setBlock(world, position.add(7, 4, 7), this.airState);
		this.setBlock(world, position.add(7, 4, 9), this.airState);
		this.setBlock(world, position.add(7, 4, 10), this.cobbleState);
		this.setBlock(world, position.add(7, 5, 0), this.cobbleState);
		this.setBlock(world, position.add(7, 5, 1), this.airState);
		this.setBlock(world, position.add(7, 5, 2), this.airState);
		this.setBlock(world, position.add(7, 5, 3), this.airState);
		this.setBlock(world, position.add(7, 5, 4), this.airState);
		this.setBlock(world, position.add(7, 5, 7), this.airState);
		this.setBlock(world, position.add(7, 5, 8), this.airState);
		this.setBlock(world, position.add(7, 5, 9), this.airState);
		this.setBlock(world, position.add(7, 5, 10), this.cobbleState);
		this.setBlock(world, position.add(7, 6, 0), this.cobbleState);
		this.setBlock(world, position.add(7, 6, 1), this.airState);
		this.setBlock(world, position.add(7, 6, 2), this.airState);
		this.setBlock(world, position.add(7, 6, 3), this.airState);
		this.setBlock(world, position.add(7, 6, 4), this.airState);
		this.setBlock(world, position.add(7, 6, 5), this.airState);
		this.setBlock(world, position.add(7, 6, 6), this.airState);
		this.setBlock(world, position.add(7, 6, 7), this.airState);
		this.setBlock(world, position.add(7, 6, 8), this.airState);
		this.setBlock(world, position.add(7, 6, 9), this.airState);
		this.setBlock(world, position.add(7, 6, 10), this.cobbleState);
		this.setBlock(world, position.add(7, 7, 0), this.cobbleState);
		this.setBlock(world, position.add(7, 7, 1), this.slabState);
		this.setBlock(world, position.add(7, 7, 2), this.slabState);
		this.setBlock(world, position.add(7, 7, 3), this.slabState);
		this.setBlock(world, position.add(7, 7, 4), this.slabState);
		this.setBlock(world, position.add(7, 7, 5), this.slabState);
		this.setBlock(world, position.add(7, 7, 6), this.airState);
		this.setBlock(world, position.add(7, 7, 7), this.slabState);
		this.setBlock(world, position.add(7, 7, 8), this.slabState);
		this.setBlock(world, position.add(7, 7, 9), this.slabState);
		this.setBlock(world, position.add(7, 7, 10), this.cobbleState);
		this.setBlock(world, position.add(7, 8, 0), this.cobbleState);
		this.setBlock(world, position.add(7, 8, 1), this.airState);
		this.setBlock(world, position.add(7, 8, 2), this.airState);
		this.setBlock(world, position.add(7, 8, 3), this.airState);
		this.setBlock(world, position.add(7, 8, 4), this.airState);
		this.setBlock(world, position.add(7, 8, 5), this.airState);
		this.setBlock(world, position.add(7, 8, 6), this.airState);
		this.setBlock(world, position.add(7, 8, 7), this.airState);
		this.setBlock(world, position.add(7, 8, 8), this.airState);
		this.setBlock(world, position.add(7, 8, 9), this.airState);
		this.setBlock(world, position.add(7, 8, 10), this.cobbleState);
		this.setBlock(world, position.add(7, 9, 0), this.cobbleState);
		this.setBlock(world, position.add(7, 9, 1), this.airState);
		this.setBlock(world, position.add(7, 9, 2), this.airState);
		this.setBlock(world, position.add(7, 9, 3), this.airState);
		this.setBlock(world, position.add(7, 9, 4), this.airState);
		this.setBlock(world, position.add(7, 9, 5), this.airState);
		this.setBlock(world, position.add(7, 9, 6), this.airState);
		this.setBlock(world, position.add(7, 9, 7), this.airState);
		this.setBlock(world, position.add(7, 9, 8), this.airState);
		this.setBlock(world, position.add(7, 9, 9), this.airState);
		this.setBlock(world, position.add(7, 9, 10), this.cobbleState);
		this.setBlock(world, position.add(7, 10, 0), this.cobbleState);
		this.setBlock(world, position.add(7, 10, 1), this.airState);
		this.setBlock(world, position.add(7, 10, 2), this.airState);
		this.setBlock(world, position.add(7, 10, 3), this.airState);
		
		this.generate2(world, rand, position);
		return true;
	}
	
	private boolean generate2(World world, Random rand, BlockPos position) {
		this.setBlock(world, position.add(7, 10, 4), this.airState);
		this.setBlock(world, position.add(7, 10, 5), this.airState);
		this.setBlock(world, position.add(7, 10, 6), this.airState);
		this.setBlock(world, position.add(7, 10, 7), this.airState);
		this.setBlock(world, position.add(7, 10, 8), this.airState);
		this.setBlock(world, position.add(7, 10, 9), this.airState);
		this.setBlock(world, position.add(7, 10, 10), this.cobbleState);
		this.setBlock(world, position.add(7, 11, 0), this.cobbleState);
		this.setBlock(world, position.add(7, 11, 1), this.airState);
		this.setBlock(world, position.add(7, 11, 2), this.airState);
		this.setBlock(world, position.add(7, 11, 3), this.airState);
		this.setBlock(world, position.add(7, 11, 4), this.airState);
		this.setBlock(world, position.add(7, 11, 5), this.airState);
		this.setBlock(world, position.add(7, 11, 6), this.airState);
		this.setBlock(world, position.add(7, 11, 7), this.airState);
		this.setBlock(world, position.add(7, 11, 8), this.airState);
		this.setBlock(world, position.add(7, 11, 9), this.airState);
		this.setBlock(world, position.add(7, 11, 10), this.cobbleState);
		this.setBlock(world, position.add(7, 12, 0), this.cobbleState);
		this.setBlock(world, position.add(7, 12, 1), this.slabState);
		this.setBlock(world, position.add(7, 12, 2), this.slabState);
		this.setBlock(world, position.add(7, 12, 3), this.slabState);
		this.setBlock(world, position.add(7, 12, 4), this.slabState);
		this.setBlock(world, position.add(7, 12, 5), this.slabState);
		this.setBlock(world, position.add(7, 12, 6), this.slabState);
		this.setBlock(world, position.add(7, 12, 7), this.slabState);
		this.setBlock(world, position.add(7, 12, 8), this.slabState);
		this.setBlock(world, position.add(7, 12, 9), this.slabState);
		this.setBlock(world, position.add(7, 12, 10), this.cobbleState);
		this.setBlock(world, position.add(7, 13, 0), this.bedrockState);
		this.setBlock(world, position.add(7, 13, 1), this.airState);
		this.setBlock(world, position.add(7, 13, 2), this.airState);
		this.setBlock(world, position.add(7, 13, 3), this.airState);
		this.setBlock(world, position.add(7, 13, 4), this.airState);
		this.setBlock(world, position.add(7, 13, 5), this.airState);
		this.setBlock(world, position.add(7, 13, 6), this.airState);
		this.setBlock(world, position.add(7, 13, 7), this.airState);
		this.setBlock(world, position.add(7, 13, 8), this.airState);
		this.setBlock(world, position.add(7, 13, 9), this.airState);
		this.setBlock(world, position.add(7, 13, 10), this.bedrockState);
		this.setBlock(world, position.add(7, 14, 0), this.bedrockState);
		this.setBlock(world, position.add(7, 14, 1), this.airState);
		this.setBlock(world, position.add(7, 14, 2), this.airState);
		this.setBlock(world, position.add(7, 14, 3), this.airState);
		this.setBlock(world, position.add(7, 14, 4), this.airState);
		this.setBlock(world, position.add(7, 14, 5), this.airState);
		this.setBlock(world, position.add(7, 14, 6), this.airState);
		this.setBlock(world, position.add(7, 14, 7), this.airState);
		this.setBlock(world, position.add(7, 14, 8), this.airState);
		this.setBlock(world, position.add(7, 14, 9), this.airState);
		this.setBlock(world, position.add(7, 14, 10), this.bedrockState);
